Workbook

Sheet work sheet_Cloning
A1: DATE | B1: Code of Egg | C1: Injection | D1: Enulceation | F1: LED | G1: Lot No. | H1: N | I1: Time | K1: Cell | M1: Remarks | N1: LOT | O1: Activated Time | P1: Observation No. | Q1: Observation Time | R1: N | S1: Activated | T1: 2-cell (0.75 h) | U1: 4-cell (1 h) | V1: 8-cell (1.25 h) | W1: 16-cell (1.5 h) | X1: 32-cell (1.75 h) | Y1: 64-cell (2 h) | Z1: 128-cell (2.25 h) | AA1: 256-cell (2.5 h) | AB1: 512-cell (2.75 h) | AC1: 1k-cell (3 h) | AD1: High (3.3 h) | AE1: Oblong (3.7 h) | AF1: Sphere (4 h) | AG1: Dome (4.3 h) | AH1: 30%epi (4.7 h) | AI1: 50%epi (5.3 h) | AJ1: Germ ring (5.7 h) | AK1: Shield (6 h) | AL1: 75%epi (8 h) | AM1: 90%epi (9 h) | AN1: Day 1 | AO1: Day 2 | AP1: Day 3
C2: Name of cell | D2: Power (%) | E2: Pulse (us) | I2: Start | J2: Finish | K2: Break | L2: no break
P3: 1
P5: 2
P7: 3
P9: 4
P11: 5
P13: 6
P15: 1
P17: 2
P19: 3
P21: 4
P23: 5
P25: 6
... P73: 6

Sheet June
A1: No | B1: DATE | C1: Code of Egg | D1: Injection | E1: Enulceation | G1: Lot No. | H1: N | I1: Time | K1: Cell | M1: Activated | N1: Activated time | O1: 2-cell (0.75 h) | P1: 4-cell (1 h) | Q1: 8-cell (1.25 h) | R1: 16-cell (1.5 h) | S1: 32-cell (1.75 h) | T1: 64-cell (2 h) | U1: 128-cell (2.25 h) | V1: 256-cell (2.5 h) | W1: 512-cell (2.75 h) | X1: 1k-cell (3 h) | Y1: High (3.3 h) | Z1: Oblong (3.7 h) | AA1: Sphere (4 h) | AB1: Dome (4.3 h) | AC1: 30%epi (4.7 h) | AD1: 50%epi (5.3 h) | AE1: Germ ring (5.7 h) | AF1: Shield (6 h) | AG1: 75%epi (8 h) | AH1: 90%epi (9 h) | AI1: Day1 | AJ1: Day2 | AK1: Remarks
D2: Name of cell | E2: Power (%) | F2: Pulse (us) | I2: Start | J2: Finish | K2: Break | L2: no break
A3: 1 | B3: 45911 | C3: E4_2025-09-11 | D3: TU dissociated cells-11 | E3: 100 | F3: 500 | G3: 1 | H3: 2 | I3: 10.02 | J3: 10.21 | K3: TRUE | L3: FALSE | M3: 2 | N3: 10.38 | O3: 2 | P3: 0 (13.42) | AK3: Used Hoechst 1:1000, หยิบมา 3 ฟอง ไม่มี mycropyle 1 ฟอง
B4: **ใช้ injector sunlight band | C4: E4_2025-09-11 | D4: TU dissociated cells-11 | E4: 100 | F4: 500 | G4: 2 | H4: 1 | I4: 10.32 | J4: 10.39 | K4: TRUE | L4: FALSE | M4: 1 | N4: 10.57 | O4: 1 | P4: 1 | Q4: 1 | R4: 1 | S4: 1 | T4: 1 | U4: 1 (normal,13.42) | V4: 1 | W4: 1 | X4: 1 (normal,15.27) | Y4: 0 (18.43) | AK4: Used Hoechst 1:1000 หยิบมา 3 ฟอง ไม่มี mycropyle 2 ฟอง
C5: E4_2025-09-11 | D5: TU dissociated cells-11 | E5: 100 | F5: 500 | G5: 3 | H5: 1 | I5: 11.12 | J5: 11.26 | K5: TRUE | L5: FALSE | M5: 1 | N5: 11.42 | O5: 1 | P5: - | Q5: 1 (abnormal,13.42) | R5: 1 | S5: 1 | T5: 1 | U5: 1 | V5: 1 (abnormal,15.27) | W5: 1 | X5: 1 | Y5: 1 | Z5: 1 | AA5: 1 (abnormal,18.43) | AB5: 0 (18.43) | AK5: Used Hoechst 1:500 หยิบมา 5 ฟอง ไม่มี mycropyle 4 ฟอง
C6: E4_2025-09-11 | D6: TU dissociated cells-11 | E6: 100 | F6: 500 | G6: 4 | H6: 1 | I6: 11.12 | J6: 11.36 | K6: TRUE | L6: FALSE | M6: 1 | N6: 11.53 | O6: 1 | P6: 0 (13.42) | AK6: Used Hoechst 1:1000
C7: E4_2025-09-11 | D7: TU dissociated cells-11 | E7: 100 | F7: 500 | G7: 5 | H7: 1 | I7: 11.39 | J7: 11.43 | K7: TRUE | L7: FALSE | M7: 1 | N7: 11.59 | O7: 1 | P7: - | Q7: 1 (abnormal,13.42) | R7: 1 | S7: 1 | T7: 1 | U7: 1 | V7: 1 (abnormal,15.27) | W7: 1 | X7: 1 | Y7: 0 (18.43) | AK7: Used Hoechst 1:1000
C8: E4_2025-09-11 | D8: TU dissociated cells-11 | E8: 100 | F8: 500 | G8: 6 | H8: 1 | I8: 0.49444444 | J8: 12.02 | K8: TRUE | L8: FALSE | M8: 1 | N8: 12.14 | O8: 1 | P8: - | Q8: 1 (abnormal,13.42) | R8: 1 | S8: 1 | T8: 1 | U8: 1 (abnormal,15.27) | V8: 1 | W8: 1 | X8: 1 | Y8: 0 (18.43) | AK8: Used Hoechst 1:1000
C9: E4_2025-09-11 | D9: TU dissociated cells-11 | E9: 100 | F9: 500 | G9: 7 | H9: 2 | I9: 12.05 | J9: 12.22 | K9: TRUE | L9: FALSE | M9: 2 | N9: 12.38 | O9: 1 | P9: 1 (abnormal,13.42) | Q9: 1 | R9: 1 | S9: 0 (15.27) | AK9: Used Hoechst 1:1000
A10: 2 | B10: 45916 | C10: E7_2025-09-16 | D10: NHGRI dissociated cells-11 | E10: 100 | F10: 500 | G10: 1 | H10: 3 | I10: 9.4 | J10: 10.04 | K10: TRUE | L10: FALSE | M10: 3 | N10: 10.22 | O10: 1 | P10: 1 | Q10: 1 | R10: 1 | S10: 1 | T10: 1 | U10: 1 (abnormal,13.15) | V10: 0 | AK10: ค่อนข้างแย่มาก ไข่ไม่ดี หา micropyle ไม่เจอเลย 100% แต่หา metaphaseII เจอ เลยต้องทำการ laser DNA จากนั้น laser บริเวณ Animal pole เพื่อสร้างรูให้ inject เซลล์
B11: **ใช้ injector sunlight band | C11: E7_2025-09-16 | D11: NHGRI dissociated cells-11 | E11: 100 | F11: 500 | G11: 2 | H11: 1 | I11: 10.09 | J11: 10.2 | K11: TRUE | L11: FALSE | M11: 1 | N11: 10.45 | O11: 1 | P11: 1 | Q11: 1 | R11: 1 | S11: 1 | T11: 1 (abnormal,13.15) | U11: 0
C12: E7_2025-09-16 | D12: NHGRI dissociated cells-11 | E12: 100 | F12: 500 | G12: 3 | H12: 5 | I12: 10.28 | J12: 10.54 | K12: TRUE | L12: FALSE | M12: 5 | N12: 11.12 | O12: 1 | P12: 1 | Q12: 1 | R12: 1 (abnormal,13.15) | S12: 0 | T12: 0
A13: 3 | B13: 45917 | C13: E4_2025-09-17 | D13: AB Chunk-01 | E13: ✖ | F13: ✖ | G13: 1 | H13: 4 | I13: 9.31 | J13: 9.42 | K13: TRUE | L13: FALSE | M13: 4 | N13: 9.59 | O13: 3 | P13: 3 | Q13: 3 | R13: 3 | S13: 3 | T13: 3 | U13: 3 | V13: 3 | W13: 3 | X13: 3 | Y13: 3 | Z13: 2 | AA13: 2 | AB13: 2 | AC13: 2 | AD13: 2 | AE13: 2 | AF13: 1 | AG13: 1 (normal,19.49) | AH13: 0 | AK13: micropyle สวยมาก ไข่ดี
B14: **ใช้ injector sunlight band | C14: E4_2025-09-17 | D14: AB Chunk-01 | E14: 100 | F14: 500 | G14: 2 | H14: 5 | I14: 9.5 | J14: 10.09 | K14: TRUE | L14: FALSE | M14: 5 | N14: 10.3 | O14: 4 | P14: 4 | Q14: 4 | R14: 4 | S14: 4 | T14: 4 | U14: 4 | V14: 4 | W14: 4 | X14: 4 | Y14: 4 | Z14: 4 | AA14: 3 | AB14: 3 | AC14: 3 | AD14: 2 | AE14: 2 | AF14: 2 | AG14: 2 (normal&ab,19.49) | AH14: 0 | AK14: โอเคดี หยิบมา 6 ฟอง ทำได้ 5 ฟอง อีกฟองไม่มี micropyle
C15: E4_2025-09-17 | D15: AB Chunk-01 | E15: 100 | F15: 500 | G15: 3 | H15: 6 | I15: 10.14 | J15: 10.38 | K15: TRUE | L15: FALSE | M15: 6 | N15: 10.54 | O15: 3 | P15: 3 | Q15: 3 | R15: 3 | S15: 3 | T15: 3 | U15: 3 | V15: 3 | W15: 3 | X15: 2 | Y15: 2 | Z15: 1 | AA15: 1 (abnormal,16.54) | AB15: 0 | AK15: เติมเซลล์ก่อนเริ่มทำ, โอเคดี
C16: E4_2025-09-17 | D16: AB Chunk-01 | E16: 100 | F16: 500 | G16: 4 | H16: 3 | I16: 10.49 | J16: 11.09 | K16: TRUE | L16: FALSE | M16: 3 | N16: 11.25 | O16: 2 | P16: 2 | Q16: 2 | R16: 2 | S16: 2 | T16: 2 | U16: 2 | V16: 2 | W16: 2 | X16: 2 | Y16: 2 | Z16: 2 | AA16: 2 | AB16: 2 | AC16: 2 | AD16: 2 | AE16: 2 | AF16: 2 | AG16: 1 (normal,19.49) | AH16: 0 | AK16: laser ให้พี่ผึ้ง 3 ฟอง ทำเอง 3 ฟอง
C17: E4_2025-09-17 | D17: AB Chunk-01 | E17: 100 | F17: 500 | G17: 5 | H17: 4 | I17: 11.12 | J17: 11.4 | K17: TRUE | L17: FALSE | M17: 4 | N17: 11.55 | O17: 1 | P17: 1 | Q17: 1 | R17: 1 | S17: 1 | T17: 1 | U17: 1 | V17: 1 | W17: 1 | X17: 1 | Y17: 1 | Z17: 1 | AA17: 1 (abnormal,16.54) | AB17: 0 | AK17: OK
C18: E4_2025-09-17 | D18: AB Chunk-01 | E18: 100 | F18: 500 | G18: 6 | H18: 5 | I18: 11.52 | J18: 12.1 | K18: TRUE | L18: FALSE | M18: 5 | N18: 12.23 | O18: 0 | P18: 0 | AK18: OK
A19: 4 | B19: 45918 | C19: E4_2025-09-18 | D19: TU dissociated cells-12 | E19: 100 | F19: 500 | G19: 1 | H19: 2 | I19: 9.45 | J19: 10.04 | K19: TRUE | L19: FALSE | M19: 2 | N19: 10.22 | O19: 1 | P19: 1 | Q19: 1 | R19: 1 | S19: 1 | T19: 1 | U19: 1 | V19: 1 | W19: 1 | X19: 1 | Y19: 1 | Z19: 1 | AA19: 1 (normal,16.00) | AB19: 0 | AK19: ไข่ E4 ในส่วนของจูน 50:50 คือ ปนทั้งที่ mycropyle สวย metaphaseII สวย ผสมกับหา micropyle ไม่เจอ แต่เห็นดีเอ็นเอ ไข่ E6 แย่มาก แทบจะหา micropyle ไม่เจอเลย **ใช้ injector gynemed band
B20: **ใช้ injector gynemed band | C20: E6_2025-09-18 | D20: TU dissociated cells-12 | E20: 100 | F20: 500 | G20: 2 | H20: 2 | I20: 10.2 | J20: 10.31 | K20: FALSE | L20: FALSE | M20: 2 | N20: 10.48 | O20: 1 | P20: 1 | Q20: 1 | R20: 1 | S20: 1 | T20: 1 | U20: 1 | V20: 1 | W20: 1 | X20: 1 | Y20: 1 | Z20: 1 | AA20: 1 | AB20: 1 | AC20: 1 | AD20: 1 | AE20: 1 | AF20: 1 (abnormal,18.39) | AG20: 0
C21: E6_2025-09-18 | D21: TU dissociated cells-12 | E21: 100 | F21: 500 | G21: 3 | H21: 3 | I21: 10.33 | J21: 10.45 | K21: TRUE | L21: FALSE | M21: 3 | N21: 11.05 | O21: 0 | P21: 0
C22: E4_2025-09-18 | D22: TU dissociated cells-12 | E22: 100 | F22: 500 | G22: 4 | H22: 5 | I22: 10.49 | J22: 10.56 | K22: TRUE | L22: FALSE | M22: 5 | N22: 11.09 | O22: 1 | P22: 1
C23: E4_2025-09-18 | D23: TU dissociated cells-12 | E23: 100 | F23: 500 | G23: 5 | H23: 6 | I23: 11.02 | J23: 11.19 | K23: TRUE | L23: FALSE | M23: 6 | N23: 11.39 | O23: 2 | P23: 2 | Q23: 1 | R23: 1 | S23: 1 | T23: 1 | U23: 1 | V23: 1 | W23: 1 | X23: 1 | Y23: 1 | Z23: 1 | AA23: 1 | AB23: 1 | AC23: 1 | AD23: 1 | AE23: 1 | AF23: 1 (normal,18.39) | AG23: 0
C24: E4_2025-09-18 | D24: TU dissociated cells-12 | E24: 100 | F24: 500 | G24: 6 | H24: 3 | I24: 11.21 | J24: 11.48 | K24: TRUE | L24: FALSE | M24: 3 | N24: 12.05 | O24: 2 | P24: 2 | Q24: 2 | R24: 1 | S24: 1 | T24: 1 | U24: 1 | V24: 1 | W24: 1 | X24: 1 | Y24: 1 | Z24: 1 (normal,17.24) | AA24: 0
C25: E4_2025-09-18 | D25: TU dissociated cells-12 | E25: 100 | F25: 500 | G25: 7 | H25: 7 | I25: 11.51 | J25: 12.19 | K25: TRUE | L25: FALSE | M25: 7 | N25: 12.35 | O25: 2 | P25: 2 | Q25: 1 | R25: 1 | S25: 1 | T25: 1 | U25: 1 | V25: 1 | W25: 1 | X25: 1 | Y25: 1 | Z25: 1 | AA25: 1 | AB25: 1 (abnormal,18.39) | AC25: 0
A26: 5 | B26: 45923 | C26: E6_2025-09-23 | D26: NHGRI dissociated cells-12 | E26: 100 | F26: 500 | G26: 1 | H26: 3 | I26: 10.02 | J26: 10.16 | K26: TRUE | L26: FALSE | M26: 3 | N26: 10.33 | O26: 1 | P26: 0 | AK26: OK ดีมาก
C27: E6_2025-09-23 | D27: NHGRI dissociated cells-12 | E27: 100 | F27: 500 | G27: 2 | H27: 3 | I27: 10.27 | J27: 10.37 | K27: TRUE | L27: FALSE | M27: 3 | N27: 10.56 | O27: 2 | P27: 2 | Q27: 2 | R27: 2 | S27: 2 | T27: 2 | U27: 2 | V27: 2 | W27: 2 | X27: 2 | Y27: 2 | Z27: 2 | AA27: 2 | AB27: 2 | AC27: 2 | AD27: 2 | AE27: 2 | AF27: 1 | AG27: 1 | AH27: 0
C28: E6_2025-09-23 | D28: NHGRI dissociated cells-12 | E28: 100 | F28: 500 | G28: 3 | H28: 4 | I28: 10.4 | J28: 11.05 | K28: TRUE | L28: FALSE | M28: 4 | N28: 11.21 | O28: 4 | P28: 4 | Q28: 4 | R28: 4 | S28: 4 | T28: 4 | U28: 4 | V28: 4 | W28: 4 | X28: 4 | Y28: 4 | Z28: 4 | AA28: 4 | AB28: 4 | AC28: 4 | AD28: 3 | AE28: 3 | AF28: 3 | AG28: 2 | AH28: 0
C29: E6_2025-09-23 | D29: NHGRI dissociated cells-12 | E29: 100 | F29: 500 | G29: 4 | H29: 5 | I29: 11.07 | J29: 11.29 | K29: TRUE | L29: FALSE | M29: 5 | N29: 11.45 | O29: 5 | P29: 5 | Q29: 5 | R29: 3 | S29: 3 | T29: 3 | U29: 3 | V29: 3 | W29: 3 | X29: 3 | Y29: 0
C30: E6_2025-09-23 | D30: NHGRI dissociated cells-12 | E30: 100 | F30: 500 | G30: 5 | H30: 1 | I30: 11.49 | J30: 11.57 | K30: TRUE | L30: FALSE | M30: 1 | N30: 12.12 | O30: 1 | P30: 1 | Q30: 1 | R30: 0
A31: 6 | B31: 45926 | C31: E5_2025-09-26 | D31: AB dissociated cells-16 | E31: 100 | F31: 500 | G31: 1 | H31: 2 | I31: 10.2 | J31: 10.29 | K31: TRUE | L31: FALSE | M31: 2 | N31: 10.47 | O31: 1 | P31: 1 | Q31: 1 | R31: 1 | S31: 1 | T31: 1 | U31: 1 | V31: 1 | W31: 1 | X31: 1 | Y31: 1 | Z31: 1 | AA31: 1 | AB31: 1 | AC31: 1 | AD31: 1 | AE31: 1 | AF31: 1 | AG31: 1 | AH31: 1 | AI31: 1 | AJ31: 1 | AK31: หยิบมา 6 ไม่เจอ micropyle 2 ใบ เลเซอร์+ฉีด ใบต่อใบ
C32: E5_2025-09-26 | D32: AB dissociated cells-16 | E32: 100 | F32: 500 | G32: 2 | H32: 2 | I32: 10.34 | J32: 10.41 | K32: TRUE | L32: FALSE | M32: 2 | N32: 10.59 | O32: 2 | P32: 2 | Q32: 2 | R32: 2 | S32: 2 | T32: 2 | U32: 2 | V32: 2 | W32: 2 | X32: 2 | Y32: 2 | Z32: 2 | AA32: 2 | AB32: 2 | AC32: 0 | AK32: หยิบมา 6 ไม่เจอ micropyle 2 ใบ เลเซอร์+ฉีด ใบต่อใบ
C33: E6_2025-09-26 | D33: AB dissociated cells-16 | E33: 100 | F33: 500 | G33: 3 | H33: 1 | I33: 10.49 | J33: 10.56 | K33: TRUE | L33: FALSE | M33: 1 | N33: 11.14 | O33: 1 | P33: 1 | Q33: 1 | R33: 1 | S33: 1 | T33: 1 | U33: 1 | V33: 1 | W33: 1 | X33: 1 | Y33: 1 | Z33: 1 | AA33: 1 | AB33: 1 | AC33: 1 | AD33: 1 | AE33: 1 | AF33: 1 | AG33: 1 | AH33: 1 | AI33: 1 | AJ33: 1 | AK33: หยิบมา 6 ไม่เจอ micropyle 1 ใบ เลเซอร์+ฉีด ใบต่อใบ
C34: E6_2025-09-26 | D34: AB dissociated cells-16 | E34: 100 | F34: 500 | G34: 4 | H34: 5 | I34: 11.02 | J34: 11.24 | K34: TRUE | L34: FALSE | M34: 5 | N34: 11.43 | O34: 1 | P34: 1 | Q34: 1 | R34: 1 | S34: 1 | T34: 1 | U34: 1 | V34: 1 | W34: 1 | X34: 1 | Y34: 1 | Z34: 1 | AA34: 0
C35: E6_2025-09-26 | D35: AB dissociated cells-16 | E35: 100 | F35: 500 | G35: 5 | H35: 6 | I35: 11.45 | J35: 12.11 | K35: TRUE | L35: FALSE | M35: 6 | N35: 12.26 | O35: 6 | P35: 6 | Q35: 2 | R35: 2 | S35: 2 | T35: 2 | U35: 2 | V35: 2 | W35: 2 | X35: 2 | Y35: 2 | Z35: 2 | AA35: 2 | AB35: 2 | AC35: 2 | AD35: 0
C36: E6_2025-09-26 | D36: AB dissociated cells-16 | E36: 100 | F36: 500 | G36: 6 | H36: 6 | I36: 12.13 | J36: 12.35 | K36: TRUE | L36: FALSE | M36: 6 | N36: 12.5 | O36: 2 | P36: 2 | Q36: 1 | R36: 1 | S36: 1 | T36: 1 | U36: 1 | V36: 1 | W36: 1 | X36: 1 | Y36: 1 | Z36: 1 | AA36: 1 | AB36: 1 | AC36: 0
A37: 7 | B37: 45930 | C37: E2_2025-09-30 | D37: TU dissociated cells-13 | E37: 100 | F37: 500 | G37: 1 | H37: 4 | I37: 10.15 | J37: 10.34 | K37: TRUE | L37: FALSE | M37: 4 | N37: 10.52 | O37: 1 | P37: 0
C38: E2_2025-09-30 | D38: TU dissociated cells-13 | E38: 100 | F38: 500 | G38: 2 | H38: 3 | I38: 10.45 | J38: 10.58 | K38: TRUE | L38: FALSE | M38: 3 | N38: 11.14 | O38: 1 | P38: 1 | Q38: 1 | R38: 1 | S38: 1 | T38: 1 | U38: 1 | V38: 1 | W38: 1 | X38: 1 | Y38: 1 | Z38: 1 | AA38: 1 | AB38: 1 | AC38: 1 | AD38: 1 | AE38: 0
C39: E2_2025-09-30 | D39: TU dissociated cells-13 | E39: 100 | F39: 500 | G39: 3 | H39: 3 | I39: 11 | J39: 11.12 | K39: TRUE | L39: FALSE | M39: 3 | N39: 11.28 | O39: 1 | P39: 1 | Q39: 1 | R39: 1 | S39: 1 | T39: 1 | U39: 1 | V39: 1 | W39: 1 | X39: 1 | Y39: 1 | Z39: 1 | AA39: 1 | AB39: 1 | AC39: 1 | AD39: 0
C40: E2_2025-09-30 | D40: TU dissociated cells-13 | E40: 100 | F40: 500 | G40: 4 | H40: 2 | I40: 11.14 | J40: 11.23 | K40: TRUE | L40: FALSE | M40: 2 | N40: 11.39 | O40: 2 | P40: 2 | Q40: 2 | R40: 2 | S40: 2 | T40: 2 | U40: 2 | V40: 2 | W40: 2 | X40: 2 | Y40: 2 | Z40: 2 | AA40: 2 | AB40: 2 | AC40: 1 | AD40: 0
...

Sheet Jan
A1: No | B1: DATE | C1: Code of Egg | D1: Injection | E1: Enulceation | G1: Lot No. | H1: N | I1: Time | K1: Activated(N) | L1: Activated time | M1: 2-cell (1 h) | N1: 4-cell (1 h) | O1: 8-cell (1.25 h) | P1: 16-cell (1.5 h) | Q1: 32-cell (1.75 h) | R1: 64-cell (2 h) | S1: 128-cell (2.25 h) | T1: 256-cell (2.5 h) | U1: 512-cell (2.75 h) | V1: 1k-cell (3 h) | W1: High (3.3 h) | X1: Oblong (3.7 h) | Y1: Sphere (4 h) | Z1: Dome (4.3 h) | AA1: 30%epi (4.7 h) | AB1: 50%epi (5.3 h) | AC1: Germ ring (5.7 h) | AD1: Shield (6 h) | AE1: 75%epi (8 h) | AF1: 90%epi (9 h) | AG1: Day1 | AH1: Day2 | AI1: clone | AJ1: Remarks | AK1: Code
D2: Name of cell | E2: Power (%) | F2: Pulse (us) | I2: Start | J2: Finish
A4: 1 | B4: 45911 | C4: E4_2025-09-11 | D4: TU11-dissociated cells | E4: 100 | F4: 500 | G4: 1 | H4: 3 | I4: 10 | J4: 10.25 | K4: 3 | L4: 10.41 | M4: 2 | N4: 2 | O4: 2 | P4: 2 | Q4: 2 | R4: 2 | S4: 2 | T4: 2 | U4: 2 | V4: 2 | W4: 2 | X4: 2 | Y4: 1 | AJ4: จำนวน N ที่ได้เป็นการ pick-up egg มาครั้งละ 5 ฟอง แต่เจอ micropyle แค่จำนวน N ที่ได้ทำ
E5: LED 80 | G5: 2 | H5: 2 | I5: 10.32 | J5: 10.55 | K5: 3 | L5: 11.11 | M5: 3 | N5: 3 | O5: 2 | P5: 2 | Q5: 2 | R5: 2 | S5: 2 | T5: 2 | U5: 2 | V5: 2 | W5: 2
G6: 3 | H6: 4 | I6: 10.57 | J6: 11.21 | K6: 4 | L6: 11.45 | M6: 2 | N6: 2 | O6: 2
G7: 4 | H7: 3 | I7: 11.31 | J7: 11.45 | K7: 3 | L7: 12.02 | M7: 2 | N7: 2 | O7: 2 | P7: 2
G8: 5 | H8: 1 | I8: 11.5 | J8: 12.04 | K8: 1 | L8: 12.19 | M8: 0
G9: 6 | H9: 4 | I9: 12.07 | J9: 12.24 | K9: 4 | L9: 12.39 | M9: 0
A10: 2 | B10: 45916 | C10: E7_2025-09-16 | D10: NHGRI11-dissociated cell | E10: 100 | F10: 500 | G10: 1 | H10: 5 | I10: 9.41 | J10: 10.1 | K10: 5 | L10: 10.27 | M10: 3 | N10: 3 | O10: 3 | P10: 3 | Q10: 3 | R10: 3 | S10: 3 | T10: 3 | U10: 3 | V10: 3 | W10: 3 | X10: 2 | Y10: 1 | AJ10: egg ไม่มี micropyle injected ตำแหน่ง animal pole เลย
E11: LED 80 | G11: 2 | H11: 2 | I11: 10.12 | J11: 10.19 | K11: 2 | L11: 10.36/10.37 | M11: 2 | N11: 1 | O11: 1 | P11: 1 | Q11: 1 | R11: 1 | S11: 1 | T11: 1 | U11: 1 | V11: 1 | W11: 1
G12: 3 | H12: 2 | I12: 10.27 | J12: 10.59 | K12: 2 | L12: 10.5 | M12: 2 | N12: 2 | O12: 2 | P12: 2 | Q12: 2 | R12: 2 | S12: 2 | T12: 2 | U12: 2 | V12: 2 | W12: 2 | X12: 2 | Y12: 2 | Z12: 1 | AA12: 1 | AB12: 1 | AC12: 1 | AD12: 1 | AE12: 1 | AF12: 1 | AG12: 1(abnormal) | AH12: 1(abnormal) | AI12: ✓ | AK12: No.1_Clone3-NHGRI cell-11
G13: 4 | H13: 4 | I13: 10.38 | J13: 10.59 | K13: 4 | L13: 11.15 | M13: 4 | N13: 4 | O13: 4 | P13: 4 | Q13: 4 | R13: 4 | S13: 2 | T13: 2 | U13: 2 | V13: 2 | W13: 2 | X13: 2
G14: 5 | H14: 1 | I14: 11.02 | J14: 11.08 | K14: 1 | L14: 11.27 | M14: 0
A15: 3 | B15: 45917 | C15: E4_2025-09-17 | D15: AB01-crank | E15: 100 | F15: 500 | G15: 1 | H15: 6 | I15: 9.48 | J15: 10.13 | K15: 6 | L15: 10.31 | M15: 3 | N15: 3 | O15: 3 | P15: 3 | Q15: 3 | R15: 3 | S15: 3 | T15: 3 | U15: 3 | V15: 1 | W15: 1 | X15: 1 | Y15: 1 | Z15: 1 | AA15: 1
E16: LED 80 | G16: 2 | H16: 5 | I16: 10.16 | J16: 10.34 | K16: 5 | L16: 10.49 | M16: 2 | N16: 2 | O16: 2 | P16: 2 | Q16: 2 | R16: 2 | S16: 2 | T16: 2
G17: 3 | H17: 5 | I17: 10.49 | J17: 11.08 | K17: 5 | L17: 11.24 | M17: 4 | N17: 4 | O17: 4 | P17: 4 | Q17: 4 | R17: 4 | S17: 4 | T17: 4 | U17: 4 | V17: 4 | W17: 4 | X17: 4 | Y17: 4 | Z17: 4
G18: 4 | H18: 6 | I18: 11.25 | J18: 11.53 | K18: 6 | L18: 12.08 | M18: 3 | N18: 3 | O18: 3 | P18: 3 | Q18: 3 | R18: 3 | S18: 3 | T18: 3 | U18: 3 | V18: 3 | W18: 3 | X18: 3 | Y18: 3 | Z18: 3
G19: 5 | H19: 5 | I19: 11.57 | J19: 12.08 | K19: 5 | L19: 12.23 | M19: 1 | N19: 1 | O19: 1 | P19: 1 | Q19: 1 | R19: 1 | S19: 1 | T19: 1 | U19: 1 | V19: 1 | W19: 1 | X19: 1 | Y19: 1 | Z19: 1
G20: Bee1 | H20: na | I20: - | J20: - | K20: na | L20: na | M20: 0
G21: Bee2 | H21: 4 | I21: - | J21: - | K21: 4 | L21: 11.15 | M21: 2 | N21: 2 | O21: 2 | P21: 2 | Q21: 2 | R21: 2 | S21: 2 | T21: 2 | U21: 2 | V21: 2 | W21: 2 | X21: 2 | Y21: 2
G22: Bee3 | H22: 3 | I22: - | J22: - | K22: 3 | L22: 11.29 | M22: 3 | N22: 3
G23: Bee4 | H23: 5 | I23: - | J23: - | K23: 5 | L23: 11.45 | M23: 4 | N23: 4 | O23: 4 | P23: 4 | Q23: 2 | R23: 1 | S23: 1 | T23: 1 | U23: 1 | V23: 1 | W23: 1 | X23: 1 | Y23: 1 | Z23: 1
G24: Bee5 | H24: 5 | I24: - | J24: - | K24: 5 | L24: 12.15 | M24: 4 | N24: 4 | O24: 4 | P24: 2 | Q24: 2 | R24: 2 | S24: 2 | T24: 2 | U24: 2 | V24: 2 | W24: 2 | X24: 2 | Y24: 1 | Z24: 1
A25: 4 | B25: 45918 | C25: E4_2025-09-18 | D25: TU12- dissociated cells | E25: 100 | F25: 500 | G25: 1 | H25: 4 | I25: - | J25: 10.05 | K25: 4 | L25: 10.21 | M25: 0
E26: LED 60 | G26: 2 | H26: 4 | I26: 10.15 | J26: 10.31 | K26: 4 | L26: 10.46 | M26: 3 | N26: 3 | O26: 3 | P26: 3 | Q26: 3 | R26: 3 | S26: 3 | T26: 3 | U26: 3 | V26: 3 | W26: 3 | X26: 3 | Y26: 3 | Z26: 2
G27: 3 | H27: 3 | I27: 10.32 | J27: 10.44 | K27: 3 | L27: 11 | M27: 2 | N27: 2 | O27: 1 | P27: 1 | Q27: 1 | R27: 1 | S27: 1 | T27: 1 | U27: 1 | V27: 1 | W27: 1 | X27: 1 | Y27: 1
G28: 4 | H28: 3 | I28: 10.46 | J28: 11.03 | K28: 3 | L28: 11.2 | M28: 2 | N28: 2 | O28: 2 | P28: 2 | Q28: 2 | R28: 2 | S28: 2 | T28: 2 | U28: 2 | V28: 2 | W28: 2 | X28: 2 | Y28: 1
G29: 5 | H29: 5 | I29: 11.03 | J29: 11.23 | K29: 5 | L29: 11.37 | M29: 4 | N29: 4 | O29: 4 | P29: 4 | Q29: 4 | R29: 4 | S29: 4 | T29: 4 | U29: 4 | V29: 4 | W29: 4 | X29: 4 | Y29: 4 | Z29: 4
G30: 6 | H30: 3 | I30: 11.23 | J30: 11.45 | K30: 3 | L30: 12.02 | M30: 4 | N30: 4 | O30: 3 | P30: 3 | Q30: 3 | R30: 3 | S30: 3 | T30: 3 | U30: 3 | V30: 3 | W30: 3 | X30: 3 | Y30: 3 | Z30: 1 | AA30: 1 | AB30: 1 | AC30: 1 | AD30: 1 | AE30: 1 | AF30: 1 | AG30: 1(Normal) | AH30: 1(Normal) | AI30: ✓ | AJ30: death at Day 8 Freeze | AK30: No.2_Clone6-TU cell-12
G31: 7 | H31: 6 | I31: 11.46 | J31: 12.13 | K31: 6 | L31: 12.29 | M31: 4 | N31: 4 | O31: 3 | P31: 3 | Q31: 3 | R31: 3 | S31: 3 | T31: 3 | U31: 3 | V31: 3 | W31: 3 | X31: 3 | Y31: 3 | Z31: 1 | AA31: 1 | AB31: 1
A32: 5 | B32: 45923 | C32: E6_2025-09-23 | D32: NHGRI12-dissociated cell | E32: 100 | F32: 500 | G32: 1 | H32: 4 | I32: 10.05 | J32: 10.22 | K32: 4 | L32: 10.39 | M32: 4 | N32: 4 | O32: 4 | P32: 4 | Q32: 4 | R32: 4 | S32: 4 | T32: 4 | U32: 4 | V32: 4 | W32: 4 | X32: 2
E33: LED 60 | G33: 2 | H33: 3 | I33: 10.24 | J33: 10.38 | K33: 3 | L33: 10.57 | M33: 2 | N33: 2 | O33: 2 | P33: 2 | Q33: 2 | R33: 2 | S33: 2 | T33: 2 | U33: 2 | V33: 2 | W33: 2 | X33: 2 | Y33: 1
G34: 3 | H34: 2 | I34: 10.45 | J34: 10.58 | K34: 2 | L34: 11.14 | M34: 2 | N34: 2 | O34: 2 | P34: 2 | Q34: 2 | R34: 2 | S34: 2 | T34: 2 | U34: 2 | V34: 2 | W34: 2 | X34: 1 | Y34: 1
G35: 4 | H35: 2 | I35: 11 | J35: 11.17 | K35: 2 | L35: 11.33 | M35: 2 | N35: 1 | O35: 1 | P35: 1 | Q35: 1 | R35: 1 | S35: 1 | T35: 1 | U35: 1 | V35: 1 | W35: 1 | X35: 1 | Y35: 1
G36: 5 | H36: 2 | I36: - | J36: 11.4 | K36: 2 | L36: 11.58 | M36: 2 | N36: 2 | O36: 2 | P36: 2 | Q36: 2 | R36: 2 | S36: 2 | T36: 2 | U36: 2 | V36: 2 | W36: 2 | X36: 2
G37: 6 | H37: 1 | I37: 11.41 | J37: 11.52 | K37: 1 | L37: 12.06 | M37: 1 | N37: 1 | O37: 1 | P37: 1 | Q37: 1 | R37: 1 | S37: 1 | T37: 1 | U37: 1 | V37: 1 | W37: 1 | X37: 1 | Y37: 1
G38: 7 | H38: 3 | I38: 12.04 | J38: 12.21 | K38: 3 | L38: 12.35 | M38: 3 | N38: 2 | O38: 2
G39: Bee1 | H39: 3 | I39: - | J39: - | K39: 3 | L39: 10.55 | M39: 2 | N39: 2 | O39: 2 | P39: 2 | Q39: 2 | R39: 2 | S39: 2 | T39: 2 | U39: 2 | V39: 1 | W39: 1 | X39: 1 | Y39: 1
G40: Bee2 | H40: 2 | I40: - | J40: - | K40: 2 | L40: 11.11 | M40: 2 | N40: 2 | O40: 2 | P40: 2 | Q40: 2 | R40: 2 | S40: 2 | T40: 2 | U40: 2 | V40: 2 | W40: 2 | X40: 2 | Y40: 2 | Z40: 1 | AA40: 1 | AB40: 1 | AC40: 1 | AD40: 1 | AE40: 1 | AF40: 1 | AG40: 1(Abnormal) | AH40: 1(Abnormal) | AI40: ✓ | AJ40: Abnormal freeze at day 3 | AK40: No.3_Clone2-NHGRI cell-12
G41: Bee3 | H41: 3 | I41: - | J41: - | K41: 3 | L41: 11.36 | M41: 3 | N41: 1 | O41: 1 | P41: 1 | Q41: 1 | R41: 1 | S41: 1 | T41: 1 | U41: 1
...

Sheet raw data
A1: No | B1: DATE | C1: Recipient egg | D1: % NBD | F1: Lot of CSOF | G1: Code of Egg | H1: Group | I1: Injection | J1: Enulceation | M1: Lot No. | N1: N | O1: Time | Q1: Activated | R1: Activated time | S1: 2-cell (1 h) | T1: 4-cell (1 h) | U1: 8-cell (1.25 h) | V1: 16-cell (1.5 h) | W1: 32-cell (1.75 h) | X1: 64-cell (2 h) | Y1: 128-cell (2.25 h) | Z1: 256-cell (2.5 h) | AA1: 512-cell (2.75 h) | AB1: 1k-cell (3 h) | AC1: High (3.3 h) | AD1: Oblong (3.7 h) | AE1: Sphere (4 h) | AF1: Dome (4.3 h) | AG1: 30%epi (4.7 h) | AH1: 50%epi (5.3 h) | AI1: Germ ring (5.7 h) | AJ1: Shield (6 h) | AK1: 75%epi (8 h) | AL1: 90%epi (9 h) | AM1: Day1 | AN1: Day2 | AO1: clone | AP1: Zebrafish normal in system | AQ1: Remarks | AR1: BY
E2: % IVF | I2: Name of cell | J2: Power (%) | K2: Pulse (us) | L2: LED | O2: Start | P2: Finish | AU2: Timepoint | AV2: N_TU | AW2: %N_TU | AX2: N_NHGRI | AY2: %N_NHGRI | AZ2: N_AB | BA2: %N_AB
A3: 1 | B3: 45911 | C3: TAB taiwan 28-6-24 | D3: 16 cell = 55% | F3: CSOF 2024-19 | G3: E4_2025-09-11 | H3: TU | I3: TU dissociated cells-11 | J3: 100 | K3: 500 | L3: 80 | M3: 1 | N3: 3 | O3: 10 | P3: 10.25 | Q3: 3 | R3: 10.41 | S3: 2 | T3: 2 | U3: 2 | V3: 2 | W3: 2 | X3: 2 | Y3: 2 | Z3: 2 | AA3: 2 | AB3: 2 | AC3: 2 | AD3: 2 | AE3: 1 | AF3: 0 | AQ3: จำนวน N ที่ได้เป็นการ pick-up egg มาครั้งละ 5 ฟอง แต่เจอ micropyle แค่จำนวน N ที่ได้ทำ | AR3: Jan | AT3: L | AU3: Total number | AV3: =SUMIFS(N$3:N$997,H$3:H$997,"TU") -> 450 | AX3: =SUMIFS(N$3:N$997,H$3:H$997,"NHGRI") -> 484 | AZ3: =SUMIFS(N$3:N$997,H$3:H$997,"AB") -> 482
D4: day 1 = 16.66 % | G4: E4_2025-09-11 | H4: TU | I4: TU dissociated cells-11 | J4: 100 | K4: 500 | M4: 2 | N4: 3 | O4: 10.32 | P4: 10.55 | Q4: 3 | R4: 11.11 | S4: 3 | T4: 3 | U4: 2 | V4: 2 | W4: 2 | X4: 2 | Y4: 2 | Z4: 2 | AA4: 2 | AB4: 2 | AC4: 2 | AD4: 0 | AT4: O | AU4: Activated | AV4: =SUMIFS(Q$3:Q$997,H$3:H$997,"TU") -> 450 | AW4: =(AV4*100)/AV3 -> 100 | AX4: =SUMIFS(Q$3:Q$997,H$3:H$997,"NHGRI") -> 484 | AY4: =(AX4*100)/AX3 -> 100 | AZ4: =SUMIFS(Q$3:Q$997,H$3:H$997,"AB") -> 482 | BA4: =(AZ4*100)/AZ3 -> 100
G5: E4_2025-09-11 | H5: TU | I5: TU dissociated cells-11 | J5: 100 | K5: 500 | M5: 3 | N5: 4 | O5: 10.57 | P5: 11.21 | Q5: 4 | R5: 11.45 | S5: 2 | T5: 2 | U5: 2 | V5: 0 | AT5: Q | AU5: 2-cell (1 h) | AV5: =SUMIFS(S$3:S$997,H$3:H$997,"TU") -> 203 | AW5: =(AV5*100)/AV3 -> 45.111111 | AX5: =SUMIFS(S$3:S$997,H$3:H$997,"NHGRI") -> 234 | AY5: =(AX5*100)/AX3 -> 48.347107 | AZ5: =SUMIFS(S$3:S$997,H$3:H$997,"AB") -> 230 | BA5: =(AZ5*100)/AZ3 -> 47.717842
G6: E4_2025-09-11 | H6: TU | I6: TU dissociated cells-11 | J6: 100 | K6: 500 | M6: 4 | N6: 3 | O6: 11.31 | P6: 11.45 | Q6: 3 | R6: 12.02 | S6: 2 | T6: 2 | U6: 2 | V6: 2 | AT6: R | AU6: 4-cell (1 h) | AV6: =SUMIFS(T$3:T$997,H$3:H$997,"TU") -> 185 | AW6: =(AV6*100)/AV3 -> 41.111111 | AX6: =SUMIFS(T$3:T$997,H$3:H$997,"NHGRI") -> 220 | AY6: =(AX6*100)/AX3 -> 45.454545 | AZ6: =SUMIFS(T$3:T$997,H$3:H$997,"AB") -> 213 | BA6: =(AZ6*100)/AZ3 -> 44.190871
G7: E4_2025-09-11 | H7: TU | I7: TU dissociated cells-11 | J7: 100 | K7: 500 | M7: 5 | N7: 1 | O7: 11.5 | P7: 12.04 | Q7: 1 | R7: 12.19 | S7: 0 | AT7: S | AU7: 8-cell (1.25 h) | AV7: =SUMIFS(U$3:U$997,H$3:H$997,"TU") -> 169 | AW7: =(AV7*100)/AV3 -> 37.555556 | AX7: =SUMIFS(U$3:U$997,H$3:H$997,"NHGRI") -> 210 | AY7: =(AX7*100)/AX3 -> 43.38843 | AZ7: =SUMIFS(U$3:U$997,H$3:H$997,"AB") -> 199 | BA7: =(AZ7*100)/AZ3 -> 41.286307
G8: E4_2025-09-11 | H8: TU | I8: TU dissociated cells-11 | J8: 100 | K8: 500 | M8: 6 | N8: 4 | O8: 12.07 | P8: 12.24 | Q8: 4 | R8: 12.39 | S8: 0 | AT8: T | AU8: 16-cell (1.5 h) | AV8: =SUMIFS(V$3:V$997,H$3:H$997,"TU") -> 156 | AW8: =(AV8*100)/AV3 -> 34.666667 | AX8: =SUMIFS(V$3:V$997,H$3:H$997,"NHGRI") -> 201 | AY8: =(AX8*100)/AX3 -> 41.528926 | AZ8: =SUMIFS(V$3:V$997,H$3:H$997,"AB") -> 179 | BA8: =(AZ8*100)/AZ3 -> 37.136929
G9: E4_2025-09-11 | H9: TU | I9: TU dissociated cells-11 | J9: 100 | K9: 500 | L9: 90 | M9: 1 | N9: 2 | O9: 10.02 | P9: 10.21 | Q9: 2 | R9: 10.38 | S9: 1 | T9: 0 | AQ9: Used Hoechst 1:1000, หยิบมา 3 ฟอง ไม่มี mycropyle 1 ฟอง | AR9: June | AT9: U | AU9: 32-cell (1.75 h) | AV9: =SUMIFS(W$3:W$997,H$3:H$997,"TU") -> 145 | AW9: =(AV9*100)/AV3 -> 32.222222 | AX9: =SUMIFS(W$3:W$997,H$3:H$997,"NHGRI") -> 193 | AY9: =(AX9*100)/AX3 -> 39.876033 | AZ9: =SUMIFS(W$3:W$997,H$3:H$997,"AB") -> 174 | BA9: =(AZ9*100)/AZ3 -> 36.099585
G10: E4_2025-09-11 | H10: TU | I10: TU dissociated cells-11 | J10: 100 | K10: 500 | M10: 2 | N10: 1 | O10: 10.32 | P10: 10.39 | Q10: 1 | R10: 10.57 | S10: 1 | T10: 1 | U10: 1 | V10: 1 | W10: 1 | X10: 1 | Y10: 1 | Z10: 1 | AA10: 1 | AB10: 1 | AC10: 0 | AQ10: Used Hoechst 1:1000 หยิบมา 3 ฟอง ไม่มี mycropyle 2 ฟอง | AT10: V | AU10: 64-cell (2 h) | AV10: =SUMIFS(X$3:X$997,H$3:H$997,"TU") -> 144 | AW10: =(AV10*100)/AV3 -> 32 | AX10: =SUMIFS(X$3:X$997,H$3:H$997,"NHGRI") -> 190 | AY10: =(AX10*100)/AX3 -> 39.256198 | AZ10: =SUMIFS(X$3:X$997,H$3:H$997,"AB") -> 173 | BA10: =(AZ10*100)/AZ3 -> 35.892116
G11: E4_2025-09-11 | H11: TU | I11: TU dissociated cells-11 | J11: 100 | K11: 500 | M11: 3 | N11: 1 | O11: 11.12 | P11: 11.26 | Q11: 1 | R11: 11.42 | S11: 1 | T11: 1 | U11: 1 | V11: 1 | W11: 1 | X11: 1 | Y11: 1 | Z11: 1 | AA11: 1 | AB11: 1 | AC11: 1 | AD11: 1 | AE11: 1 | AF11: 0 | AQ11: Used Hoechst 1:500 หยิบมา 5 ฟอง ไม่มี mycropyle 4 ฟอง | AT11: W | AU11: 128-cell (2.25 h) | AV11: =SUMIFS(Y$3:Y$997,H$3:H$997,"TU") -> 143 | AW11: =(AV11*100)/AV3 -> 31.777778 | AX11: =SUMIFS(Y$3:Y$997,H$3:H$997,"NHGRI") -> 180 | AY11: =(AX11*100)/AX3 -> 37.190083 | AZ11: =SUMIFS(Y$3:Y$997,H$3:H$997,"AB") -> 169 | BA11: =(AZ11*100)/AZ3 -> 35.062241
G12: E4_2025-09-11 | H12: TU | I12: TU dissociated cells-11 | J12: 100 | K12: 500 | M12: 4 | N12: 1 | O12: 11.12 | P12: 11.36 | Q12: 1 | R12: 11.53 | S12: 1 | T12: 0 | AQ12: Used Hoechst 1:1000 | AT12: X | AU12: 256-cell (2.5 h) | AV12: =SUMIFS(Z$3:Z$997,H$3:H$997,"TU") -> 140 | AW12: =(AV12*100)/AV3 -> 31.111111 | AX12: =SUMIFS(Z$3:Z$997,H$3:H$997,"NHGRI") -> 178 | AY12: =(AX12*100)/AX3 -> 36.77686 | AZ12: =SUMIFS(Z$3:Z$997,H$3:H$997,"AB") -> 169 | BA12: =(AZ12*100)/AZ3 -> 35.062241
G13: E4_2025-09-11 | H13: TU | I13: TU dissociated cells-11 | J13: 100 | K13: 500 | M13: 5 | N13: 1 | O13: 11.39 | P13: 11.43 | Q13: 1 | R13: 11.59 | S13: 1 | T13: 1 | U13: 1 | V13: 1 | W13: 1 | X13: 1 | Y13: 1 | Z13: 1 | AA13: 1 | AB13: 1 | AC13: 0 | AQ13: Used Hoechst 1:1000 | AT13: Y | AU13: 512-cell (2.75 h) | AV13: =SUMIFS(AA$3:AA$997,H$3:H$997,"TU") -> 135 | AW13: =(AV13*100)/AV3 -> 30 | AX13: =SUMIFS(AA$3:AA$997,H$3:H$997,"NHGRI") -> 172 | AY13: =(AX13*100)/AX3 -> 35.53719 | AZ13: =SUMIFS(AA$3:AA$997,H$3:H$997,"AB") -> 164 | BA13: =(AZ13*100)/AZ3 -> 34.024896
G14: E4_2025-09-11 | H14: TU | I14: TU dissociated cells-11 | J14: 100 | K14: 500 | M14: 6 | N14: 1 | O14: 0.49444444 | P14: 12.02 | Q14: 1 | R14: 12.14 | S14: 1 | T14: 1 | U14: 1 | V14: 1 | W14: 1 | X14: 1 | Y14: 1 | Z14: 1 | AA14: 1 | AB14: 1 | AC14: 0 | AQ14: Used Hoechst 1:1000 | AT14: Z | AU14: 1k-cell (3 h) | AV14: =SUMIFS(AB$3:AB$997,H$3:H$997,"TU") -> 134 | AW14: =(AV14*100)/AV3 -> 29.777778 | AX14: =SUMIFS(AB$3:AB$997,H$3:H$997,"NHGRI") -> 168 | AY14: =(AX14*100)/AX3 -> 34.710744 | AZ14: =SUMIFS(AB$3:AB$997,H$3:H$997,"AB") -> 157 | BA14: =(AZ14*100)/AZ3 -> 32.572614
G15: E4_2025-09-11 | H15: TU | I15: TU dissociated cells-11 | J15: 100 | K15: 500 | M15: 7 | N15: 2 | O15: 12.05 | P15: 12.22 | Q15: 2 | R15: 12.38 | S15: 1 | T15: 1 | U15: 1 | V15: 1 | W15: 0 | AQ15: Used Hoechst 1:1000 | AT15: AA | AU15: High (3.3 h) | AV15: =SUMIFS(AC$3:AC$997,H$3:H$997,"TU") -> 120 | AW15: =(AV15*100)/AV3 -> 26.666667 | AX15: =SUMIFS(AC$3:AC$997,H$3:H$997,"NHGRI") -> 162 | AY15: =(AX15*100)/AX3 -> 33.471074 | AZ15: =SUMIFS(AC$3:AC$997,H$3:H$997,"AB") -> 147 | BA15: =(AZ15*100)/AZ3 -> 30.497925
A16: 2 | B16: 45916 | C16: TAB taiwan 28-11-24 | D16: 2 cell = 62.5 % | E16: IVF 7 before sphere = 10 % | F16: CSOF 2024-19 | G16: E7_2025-09-16 | H16: NHGRI | I16: NHGRI dissociated cells-11 | J16: 100 | K16: 500 | L16: 80 | M16: 1 | N16: 5 | O16: 9.41 | P16: 10.1 | Q16: 5 | R16: 10.27 | S16: 3 | T16: 3 | U16: 3 | V16: 3 | W16: 3 | X16: 3 | Y16: 3 | Z16: 3 | AA16: 3 | AB16: 3 | AC16: 3 | AD16: 2 | AE16: 1 | AF16: 0 | AQ16: egg ไม่มี micropyle injected ตำแหน่ง animal pole เลย No.1_Abnormal;Freeze-80@2025-09-30 Day6 | AR16: Jan | AT16: AB | AU16: Oblong (3.7 h) | AV16: =SUMIFS(AD$3:AD$997,H$3:H$997,"TU") -> 110 | AW16: =(AV16*100)/AV3 -> 24.444444 | AX16: =SUMIFS(AD$3:AD$997,H$3:H$997,"NHGRI") -> 146 | AY16: =(AX16*100)/AX3 -> 30.165289 | AZ16: =SUMIFS(AD$3:AD$997,H$3:H$997,"AB") -> 131 | BA16: =(AZ16*100)/AZ3 -> 27.178423
D17: day 1 =9.375 % | E17: Day 1 = 10 % | G17: E7_2025-09-16 | H17: NHGRI | I17: NHGRI dissociated cells-11 | J17: 100 | K17: 500 | M17: 2 | N17: 2 | O17: 10.12 | P17: 10.19 | Q17: 2 | R17: 10.36/10.37 | S17: 2 | T17: 1 | U17: 1 | V17: 1 | W17: 1 | X17: 1 | Y17: 1 | Z17: 1 | AA17: 1 | AB17: 1 | AC17: 1 | AD17: 0 | AT17: AC | AU17: Sphere (4 h) | AV17: =SUMIFS(AE$3:AE$997,H$3:H$997,"TU") -> 102 | AW17: =(AV17*100)/AV3 -> 22.666667 | AX17: =SUMIFS(AE$3:AE$997,H$3:H$997,"NHGRI") -> 127 | AY17: =(AX17*100)/AX3 -> 26.239669 | AZ17: =SUMIFS(AE$3:AE$997,H$3:H$997,"AB") -> 114 | BA17: =(AZ17*100)/AZ3 -> 23.651452
E18: IVF 7 after higt =24 % | G18: E7_2025-09-16 | H18: NHGRI | I18: NHGRI dissociated cells-11 | J18: 100 | K18: 500 | M18: 3 | N18: 2 | O18: 10.27 | P18: 10.59 | Q18: 2 | R18: 10.5 | S18: 2 | T18: 2 | U18: 2 | V18: 2 | W18: 2 | X18: 2 | Y18: 2 | Z18: 2 | AA18: 2 | AB18: 2 | AC18: 2 | AD18: 2 | AE18: 2 | AF18: 1 | AG18: 1 | AH18: 1 | AI18: 1 | AJ18: 1 | AK18: 1 | AL18: 1 | AM18: 1 | AN18: 1 | AO18: 1 | AP18: 0 | AT18: AD | AU18: Dome (4.3 h) | AV18: =SUMIFS(AF$3:AF$997,H$3:H$997,"TU") -> 64 | AW18: =(AV18*100)/AV3 -> 14.222222 | AX18: =SUMIFS(AF$3:AF$997,H$3:H$997,"NHGRI") -> 93 | AY18: =(AX18*100)/AX3 -> 19.214876 | AZ18: =SUMIFS(AF$3:AF$997,H$3:H$997,"AB") -> 79 | BA18: =(AZ18*100)/AZ3 -> 16.390041
E19: Day 1 = 4 % | G19: E7_2025-09-16 | H19: NHGRI | I19: NHGRI dissociated cells-11 | J19: 100 | K19: 500 | M19: 4 | N19: 4 | O19: 10.38 | P19: 10.59 | Q19: 4 | R19: 11.15 | S19: 4 | T19: 4 | U19: 4 | V19: 4 | W19: 4 | X19: 4 | Y19: 2 | Z19: 2 | AA19: 2 | AB19: 2 | AC19: 2 | AD19: 2 | AE19: 0 | AT19: AE | AU19: 30%epi (4.7 h) | AV19: =SUMIFS(AG$3:AG$997,H$3:H$997,"TU") -> 39 | AW19: =(AV19*100)/AV3 -> 8.6666667 | AX19: =SUMIFS(AG$3:AG$997,H$3:H$997,"NHGRI") -> 79 | AY19: =(AX19*100)/AX3 -> 16.322314 | AZ19: =SUMIFS(AG$3:AG$997,H$3:H$997,"AB") -> 54 | BA19: =(AZ19*100)/AZ3 -> 11.20332
G20: E7_2025-09-16 | H20: NHGRI | I20: NHGRI dissociated cells-11 | J20: 100 | K20: 500 | M20: 5 | N20: 1 | O20: 11.02 | P20: 11.08 | Q20: 1 | R20: 11.27 | S20: 0 | AT20: AF | AU20: 50%epi (5.3 h) | AV20: =SUMIFS(AH$3:AH$997,H$3:H$997,"TU") -> 24 | AW20: =(AV20*100)/AV3 -> 5.3333333 | AX20: =SUMIFS(AH$3:AH$997,H$3:H$997,"NHGRI") -> 68 | AY20: =(AX20*100)/AX3 -> 14.049587 | AZ20: =SUMIFS(AH$3:AH$997,H$3:H$997,"AB") -> 38 | BA20: =(AZ20*100)/AZ3 -> 7.8838174
G21: E7_2025-09-16 | H21: NHGRI | I21: NHGRI dissociated cells-11 | J21: 100 | K21: 500 | L21: 86 | M21: 1 | N21: 3 | O21: 9.4 | P21: 10.04 | Q21: 3 | R21: 10.22 | S21: 1 | T21: 1 | U21: 1 | V21: 1 | W21: 1 | X21: 1 | Y21: 1 | Z21: 0 | AQ21: ค่อนข้างแย่มาก ไข่ไม่ดี หา micropyle ไม่เจอเลย 100% แต่หา metaphaseII เจอ เลยต้องทำการ laser DNA จากนั้น laser บริเวณ Animal pole เพื่อสร้างรูให้ inject เซลล์ | AR21: June | AT21: AG | AU21: Germ ring (5.7 h) | AV21: =SUMIFS(AI$3:AI$997,H$3:H$997,"TU") -> 22 | AW21: =(AV21*100)/AV3 -> 4.8888889 | AX21: =SUMIFS(AH$3:AH$997,H$3:H$997,"NHGRI") -> 68 | AY21: =(AX21*100)/AX3 -> 14.049587 | AZ21: =SUMIFS(AI$3:AI$997,H$3:H$997,"AB") -> 36 | BA21: =(AZ21*100)/AZ3 -> 7.4688797
G22: E7_2025-09-16 | H22: NHGRI | I22: NHGRI dissociated cells-11 | J22: 100 | K22: 500 | M22: 2 | N22: 1 | O22: 10.09 | P22: 10.2 | Q22: 1 | R22: 10.45 | S22: 1 | T22: 1 | U22: 1 | V22: 1 | W22: 1 | X22: 1 | Y22: 0 | AT22: AH | AU22: Shield (6 h) | AV22: =SUMIFS(AJ$3:AJ$997,H$3:H$997,"TU") -> 20 | AW22: =(AV22*100)/AV3 -> 4.4444444 | AX22: =SUMIFS(AJ$3:AJ$997,H$3:H$997,"NHGRI") -> 56 | AY22: =(AX22*100)/AX3 -> 11.570248 | AZ22: =SUMIFS(AJ$3:AJ$997,H$3:H$997,"AB") -> 29 | BA22: =(AZ22*100)/AZ3 -> 6.0165975
G23: E7_2025-09-16 | H23: NHGRI | I23: NHGRI dissociated cells-11 | J23: 100 | K23: 500 | M23: 3 | N23: 5 | O23: 10.28 | P23: 10.54 | Q23: 5 | R23: 11.12 | S23: 1 | T23: 1 | U23: 1 | V23: 1 | W23: 0 | AT23: AI | AU23: 75%epi (8 h) | AV23: =SUMIFS(AK$3:AK$997,H$3:H$997,"TU") -> 11 | AW23: =(AV23*100)/AV3 -> 2.4444444 | AX23: =SUMIFS(AK$3:AK$997,H$3:H$997,"NHGRI") -> 51 | AY23: =(AX23*100)/AX3 -> 10.53719 | AZ23: =SUMIFS(AK$3:AK$997,H$3:H$997,"AB") -> 19 | BA23: =(AZ23*100)/AZ3 -> 3.9419087
A24: 3 | B24: 45917 | C24: TAB taiwan 20-3-25 | D24: 64 cell = 93.33% | E24: IVF 4 before 4 cell = 74 % | F24: CSOF 6-8-25 | G24: E4_2025-09-17 | H24: AB | I24: AB Chunk-01 | J24: 100 | K24: 500 | L24: 80 | M24: 1 | N24: 6 | O24: 9.48 | P24: 10.13 | Q24: 6 | R24: 10.31 | S24: 3 | T24: 3 | U24: 3 | V24: 3 | W24: 3 | X24: 3 | Y24: 3 | Z24: 3 | AA24: 3 | AB24: 1 | AC24: 1 | AD24: 1 | AE24: 1 | AF24: 1 | AG24: 1 | AH24: 0 | AR24: Jan | AT24: AJ | AU24: 90%epi (9 h) | AV24: =SUMIFS(AL$3:AL$997,H$3:H$997,"TU") -> 8 | AW24: =(AV24*100)/AV3 -> 1.7777778 | AX24: =SUMIFS(AL$3:AL$997,H$3:H$997,"NHGRI") -> 34 | AY24: =(AX24*100)/AX3 -> 7.0247934 | AZ24: =SUMIFS(AL$3:AL$997,H$3:H$997,"AB") -> 14 | BA24: =(AZ24*100)/AZ3 -> 2.9045643
D25: day 1 = 71.66 % | E25: Day 1 = 54 % | G25: E4_2025-09-17 | H25: AB | I25: AB Chunk-01 | J25: 100 | K25: 500 | M25: 2 | N25: 5 | O25: 10.16 | P25: 10.34 | Q25: 5 | R25: 10.49 | S25: 2 | T25: 2 | U25: 2 | V25: 2 | W25: 2 | X25: 2 | Y25: 2 | Z25: 2 | AA25: 0 | AT25: AK | AU25: Day1 | AV25: =SUMIFS(AM$3:AM$997,H$3:H$997,"TU") -> 8 | AW25: =(AV25*100)/AV3 -> 1.7777778 | AX25: =SUMIFS(AM$3:AM$997,H$3:H$997,"NHGRI") -> 27 | AY25: =(AX25*100)/AX3 -> 5.5785124 | AZ25: =SUMIFS(AM$3:AM$997,H$3:H$997,"AB") -> 11 | BA25: =(AZ25*100)/AZ3 -> 2.2821577
E26: IVF 4 after 64 cell = 74 % | G26: E4_2025-09-17 | H26: AB | I26: AB Chunk-01 | J26: 100 | K26: 500 | M26: 3 | N26: 5 | O26: 10.49 | P26: 11.08 | Q26: 5 | R26: 11.24 | S26: 4 | T26: 4 | U26: 4 | V26: 4 | W26: 4 | X26: 4 | Y26: 4 | Z26: 4 | AA26: 4 | AB26: 4 | AC26: 4 | AD26: 4 | AE26: 4 | AF26: 4 | AG26: 0 | AT26: AL | AU26: Day2 | AV26: =SUMIFS(AN$3:AN$997,H$3:H$997,"TU") -> 8 | AW26: =(AV26*100)/AV3 -> 1.7777778 | AX26: =SUMIFS(AN$3:AN$997,H$3:H$997,"NHGRI") -> 27 | AY26: =(AX26*100)/AX3 -> 5.5785124 | AZ26: =SUMIFS(AN$3:AN$997,H$3:H$997,"AB") -> 11 | BA26: =(AZ26*100)/AZ3 -> 2.2821577
E27: Day 1 = 60 % | G27: E4_2025-09-17 | H27: AB | I27: AB Chunk-01 | J27: 100 | K27: 500 | M27: 4 | N27: 6 | O27: 11.25 | P27: 11.53 | Q27: 6 | R27: 12.08 | S27: 3 | T27: 3 | U27: 3 | V27: 3 | W27: 3 | X27: 3 | Y27: 3 | Z27: 3 | AA27: 3 | AB27: 3 | AC27: 3 | AD27: 3 | AE27: 3 | AF27: 3 | AG27: 0
G28: E4_2025-09-17 | H28: AB | I28: AB Chunk-01 | J28: 100 | K28: 500 | M28: 5 | N28: 5 | O28: 11.57 | P28: 12.08 | Q28: 5 | R28: 12.23 | S28: 1 | T28: 1 | U28: 1 | V28: 1 | W28: 1 | X28: 1 | Y28: 1 | Z28: 1 | AA28: 1 | AB28: 1 | AC28: 1 | AD28: 1 | AE28: 1 | AF28: 1 | AG28: 0
G29: E4_2025-09-17 | H29: AB | I29: AB Chunk-01 | J29: 100 | K29: 500 | M29: Bee1 | N29: na | O29: - | P29: - | Q29: na | R29: na | S29: 0
G30: E4_2025-09-17 | H30: AB | I30: AB Chunk-01 | J30: 100 | K30: 500 | M30: Bee2 | N30: 4 | O30: - | P30: - | Q30: 4 | R30: 11.15 | S30: 2 | T30: 2 | U30: 2 | V30: 2 | W30: 2 | X30: 2 | Y30: 2 | Z30: 2 | AA30: 2 | AB30: 2 | AC30: 2 | AD30: 2 | AE30: 2 | AF30: 0
G31: E4_2025-09-17 | H31: AB | I31: AB Chunk-01 | J31: 100 | K31: 500 | M31: Bee3 | N31: 3 | O31: - | P31: - | Q31: 3 | R31: 11.29 | S31: 3 | T31: 3 | U31: 0
G32: E4_2025-09-17 | H32: AB | I32: AB Chunk-01 | J32: 100 | K32: 500 | M32: Bee4 | N32: 5 | O32: - | P32: - | Q32: 5 | R32: 11.45 | S32: 4 | T32: 4 | U32: 4 | V32: 4 | W32: 2 | X32: 1 | Y32: 1 | Z32: 1 | AA32: 1 | AB32: 1 | AC32: 1 | AD32: 1 | AE32: 1 | AF32: 1 | AG32: 0
G33: E4_2025-09-17 | H33: AB | I33: AB Chunk-01 | J33: 100 | K33: 500 | M33: Bee5 | N33: 5 | O33: - | P33: - | Q33: 5 | R33: 12.15 | S33: 4 | T33: 4 | U33: 4 | V33: 2 | W33: 2 | X33: 2 | Y33: 2 | Z33: 2 | AA33: 2 | AB33: 2 | AC33: 2 | AD33: 2 | AE33: 1 | AF33: 1 | AG33: 0
G34: E4_2025-09-17 | H34: AB | I34: AB Chunk-01 | J34: ✖ | K34: ✖ | L34: 86 | M34: 1 | N34: 4 | O34: 9.31 | P34: 9.42 | Q34: 4 | R34: 9.59 | S34: 3 | T34: 3 | U34: 3 | V34: 3 | W34: 3 | X34: 3 | Y34: 3 | Z34: 3 | AA34: 3 | AB34: 3 | AC34: 3 | AD34: 2 | AE34: 2 | AF34: 2 | AG34: 2 | AH34: 2 | AI34: 2 | AJ34: 1 | AK34: 1 | AL34: 0 | AQ34: micropyle สวยมาก ไข่ดี | AR34: June
G35: E4_2025-09-17 | H35: AB | I35: AB Chunk-01 | J35: 100 | K35: 500 | M35: 2 | N35: 5 | O35: 9.5 | P35: 10.09 | Q35: 5 | R35: 10.3 | S35: 4 | T35: 4 | U35: 4 | V35: 4 | W35: 4 | X35: 4 | Y35: 4 | Z35: 4 | AA35: 4 | AB35: 4 | AC35: 4 | AD35: 4 | AE35: 3 | AF35: 3 | AG35: 3 | AH35: 2 | AI35: 2 | AJ35: 2 | AK35: 2 | AL35: 0 | AQ35: โอเคดี หยิบมา 6 ฟอง ทำได้ 5 ฟอง อีกฟองไม่มี micropyle
G36: E4_2025-09-17 | H36: AB | I36: AB Chunk-01 | J36: 100 | K36: 500 | M36: 3 | N36: 6 | O36: 10.14 | P36: 10.38 | Q36: 6 | R36: 10.54 | S36: 3 | T36: 3 | U36: 3 | V36: 3 | W36: 3 | X36: 3 | Y36: 3 | Z36: 3 | AA36: 3 | AB36: 2 | AC36: 2 | AD36: 1 | AE36: 1 | AF36: 0 | AQ36: เติมเซลล์ก่อนเริ่มทำ, โอเคดี
G37: E4_2025-09-17 | H37: AB | I37: AB Chunk-01 | J37: 100 | K37: 500 | M37: 4 | N37: 3 | O37: 10.49 | P37: 11.09 | Q37: 3 | R37: 11.25 | S37: 2 | T37: 2 | U37: 2 | V37: 2 | W37: 2 | X37: 2 | Y37: 2 | Z37: 2 | AA37: 2 | AB37: 2 | AC37: 2 | AD37: 2 | AE37: 2 | AF37: 2 | AG37: 2 | AH37: 2 | AI37: 2 | AJ37: 2 | AK37: 1 | AL37: 0 | AQ37: laser ให้พี่ผึ้ง 3 ฟอง ทำเอง 3 ฟอง
G38: E4_2025-09-17 | H38: AB | I38: AB Chunk-01 | J38: 100 | K38: 500 | M38: 5 | N38: 4 | O38: 11.12 | P38: 11.4 | Q38: 4 | R38: 11.55 | S38: 1 | T38: 1 | U38: 1 | V38: 1 | W38: 1 | X38: 1 | Y38: 1 | Z38: 1 | AA38: 1 | AB38: 1 | AC38: 1 | AD38: 1 | AE38: 1 | AF38: 0 | AQ38: OK
G39: E4_2025-09-17 | H39: AB | I39: AB Chunk-01 | J39: 100 | K39: 500 | M39: 6 | N39: 5 | O39: 11.52 | P39: 12.1 | Q39: 5 | R39: 12.23 | S39: 0 | T39: 0 | AQ39: OK
A40: 4 | B40: 45918 | C40: TAB taiwan 20-3-25 | D40: NBD 4 128 cell =100 % | E40: IVF 4 before 16 cell = 40 % | F40: CSOF 2024-19 | G40: E4_2025-09-18 | H40: TU | I40: TU dissociated cells-12 | J40: 100 | K40: 500 | L40: 60 | M40: 1 | N40: 4 | O40: - | P40: 10.05 | Q40: 4 | R40: 10.21 | S40: 0 | AR40: Jan
...

Sheet Summary
A1: Name of cell | B1: Number of Section (50 section) | C1: No. of embryo | D1: No. of clone embryo | F1: % of normal | G1: % of abnormal | H1: normal in system
A2: AB | B2: 9 | C2: ='raw data'!AZ3 -> 482 | D2: Normal | E2: 4 | F2: =(E2*100)/C2 -> 0.82987552 | G2: =(E3*100)/C2 -> 1.4522822 | H2: 4
D3: Abnormal | E3: 7
A4: TU | B4: 7 | C4: ='raw data'!AV3 -> 450 | D4: Normal | E4: 5 | F4: =(E4*100)/C4 -> 1.1111111 | G4: =(E5*100)/C4 -> 0.66666667 | H4: 3
D5: Abnormal | E5: 3
A6: NHGRI | B6: 6 | C6: ='raw data'!AX3 -> 484 | D6: Normal | E6: 6 | F6: =(E6*100)/C6 -> 1.2396694 | G6: =(E7*100)/C6 -> 1.2396694 | H6: 5
D7: Abnormal | E7: 6
A8: Total | B8: =SUM(B2,B4,B6) -> 22 | C8: =SUM(C2:C6) -> 1416 | E8: =SUM(E2:E7) -> 31 | H8: =SUM(H2:H6) -> 12
A10: DOB | B10: Name of cell | C10: Normal | D10: Abnormal | E10: Code | F10: Date of Freeze -20 | G10: Lot.CSOF | H10: Remarks | I10: Status (@2025-11-11) | J10: Zebrafish box | K10: Remarks
A11: 45916 | B11: NHGRI dissociated cells-11 | C11: 0 | D11: 1 | E11: No.1_Clone3-NHGRI cell-11 | F11: 45922 | G11: CSOF 2024-19 | H11: alive/abnormal freeze at Day 6 | I11: Freeze | J11: -
A12: 45918 | B12: TU dissociated cells-12 | C12: 1 | D12: 0 | E12: No.2_Clone6-TU cell-12 | F12: 45926 | G12: CSOF 2024-19 | H12: death at day 8 | I12: Freeze | J12: -
A13: 45923 | B13: NHGRI dissociated cells-12 | C13: 0 | D13: 1 | E13: No.3_Clone2-NHGRI cell-12 | F13: 45930 | G13: CSOF 2024-27 | H13: alive/abnormal freeze at Day 7 | I13: Freeze | J13: -
A14: 45923 | B14: NHGRI dissociated cells-12 | C14: 0 | D14: 1 | E14: No.4_Clone3-NHGRI cell-12 | F14: 45930 | G14: CSOF 2024-27 | H14: alive/abnormal freeze at Day 7 | I14: Freeze | J14: -
A15: 45926 | B15: AB dissociated cells-16 | C15: 0 | D15: 1 | E15: No.5_Clone1-AB cell-16 | F15: 45930 | G15: CSOF 2024-27 | H15: alive/abnormal freeze at Day 7 | I15: Freeze | J15: -
A16: 45926 | B16: AB dissociated cells-16 | C16: 1 | D16: 0 | E16: No.6_Clone3-AB cell-16 | F16: Alive | G16: CSOF 2024-27 | H16: Normal alive at fish room 2025-09-29 | I16: Day 46 | J16: 1
A17: 45926 | B17: AB dissociated cells-16 | C17: 0 | D17: 1 | E17: No.7_Clone5-AB cell-16 | F17: 45930 | G17: CSOF 2024-27 | H17: alive/abnormal freeze at Day 4 | I17: Freeze | J17: -
A18: 45932 | B18: NHGRI dissociated cells-13 | C18: 0 | D18: 1 | E18: No.8_Clone5-NHGRI cell-13 | F18: 45932 | G18: CSOF 2024-27 | H18: alive/abnormal freeze at Day 4 | I18: Freeze | J18: -
A19: 45933 | B19: AB dissociated cells-17 | C19: 0 | D19: 1 | E19: No.9_Clone4-AB cell-17 | F19: - | G19: CSOF 2024-27 | H19: Alive abnormal/degenerate | I19: Disscard | J19: -
A20: 45933 | B20: AB dissociated cells-17 | C20: 0 | D20: 1 | E20: No.10_Clone4-AB cell-17 | F20: 45940 | G20: CSOF 2024-27 | H20: alive/abnormal freeze at Day 7 | I20: Freeze | J20: -
A21: 45933 | B21: AB dissociated cells-17 | C21: 1 | D21: 0 | E21: No.11_Clone4-AB cell-17 | F21: Alive | G21: CSOF 2024-27 | H21: Alive normal / fish room | I21: Day 39 | J21: 2
A22: 45937 | B22: TU dissociated cells-13 | C22: 0 | D22: 1 | E22: No.12_Clone2-TU cell-13 | F22: 45940 | G22: CSOF 2024-19 | H22: alive/abnormal freeze at Day 3 | I22: Freeze | J22: -
A23: 45937 | B23: TU dissociated cells-13 | C23: 0 | D23: 1 | E23: No.13_Clone5-TU cell-13 | F23: 45940 | G23: CSOF 2024-19 | H23: alive/abnormal freeze at Day 3 | I23: Freeze | J23: -
A24: 45940 | B24: NHGRI dissociated cells-14 | C24: 1 | D24: 0 | E24: No.14_Clone4-NHGRI-14 | F24: Alive | G24: CSOF 2024-19 | H24: Normal alive at fish room 2025-10-13 | I24: Day 32 | J24: 3
A25: 45944 | B25: AB dissociated cells-18 | C25: 0 | D25: 1 | E25: No.15_Clone5-AB cell-18 | F25: 45947 | G25: CSOF 2024-19 | H25: alive/abnormal freeze at Day 3 | I25: Freeze | J25: -
A26: 45944 | B26: AB dissociated cells-18 | C26: 0 | D26: 1 | E26: No.16_Clone6-AB cell-18 | F26: 45947 | G26: CSOF 2024-19 | H26: alive/abnormal freeze at Day 3 | I26: Freeze | J26: -
A27: 45946 | B27: NHGRI Chunks cells-1 | C27: 0 | D27: 1 | E27: No.17_Clone3-NHGRI cell-01 | F27: 45951 | G27: CSOF 2024-19 | H27: alive/abnormal freeze at Day 5 | I27: Freeze | J27: -
A28: 45950 | B28: NHGRI dissociated cells-15 | C28: 1 | D28: 0 | E28: No.18_Clone3-NHGRI cell-15 | F28: Alive | G28: CSOF 2021-16 | H28: Alive normal | I28: Day 22 | J28: 4 | K28: Box-4 There were 5 fish. One died, so 4 are left.
A29: 45950 | B29: NHGRI dissociated cells-15 | C29: 1 | D29: 0 | E29: No.19_Clone1-NHGRI cell-15 | F29: Alive | G29: CSOF 2021-16 | H29: Alive normal | I29: Day 22 | J29: 4
A30: 45950 | B30: NHGRI dissociated cells-15 | C30: 1 | D30: 0 | E30: No.20_Clone1-NHGRI cell-15 | F30: Alive | G30: CSOF 2021-16 | H30: Alive normal | I30: Day 22 | J30: 4
A31: 45950 | B31: NHGRI dissociated cells-15 | C31: 1 | D31: 0 | E31: No.21_Clone4-NHGRI cell-15 | F31: Alive | G31: CSOF 2021-16 | H31: Alive normal | I31: Day 22 | J31: 4
A32: 45950 | B32: NHGRI dissociated cells-15 | C32: 0 | D32: 1 | E32: No.22_Clone5-NHGRI cell-15 | F32: 45953 | G32: CSOF 2021-16 | H32: Abnormal,short-tailed zebrafish | I32: Freeze | J32: -
A33: 45950 | B33: NHGRI dissociated cells-15 | C33: 1 | D33: 0 | E33: No.23_Clone1-NHGRI cell-15 | F33: Alive | G33: CSOF 2021-16 | H33: Alive normal | I33: Day 22 | J33: 4
A34: 45952 | B34: AB dissociated cells-19 | C34: 1 | D34: 0 | E34: No.24_Clone6-AB cell-19 | F34: Alive | G34: CSOF 2021-16 | H34: Alive abnormal/ degenerate at day 8 | I34: Disscard | J34: -
A35: 45960 | B35: TU Chunks cells-01 | C35: 1 | D35: 0 | E35: No.25_Clone7-TU cell-01 | F35: Alive | H35: Alive normal | I35: Day 12 | J35: 5
A36: 45964 | B36: TU Chunks cells-02 | C36: 0 | D36: 1 | E36: No.26_Clone4-TU cell-02 | F36: 45970 | H36: alive/abnormal freeze at Day 6 | I36: Freeze | J36: -
A37: 45964 | B37: TU Chunks cells-02 | C37: 1 | D37: 0 | E37: No.27_Clone1-TU cell-02 | F37: Alive | H37: Alive normal | I37: Day 8 | J37: 6 | K37: Box-6 There were 3 fish. One died, so 2 are left.
A38: 45964 | B38: TU Chunks cells-02 | C38: 1 | D38: 0 | E38: No.28_Clone1-TU cell-02 | F38: Alive | H38: Alive normal | I38: Day 8 | J38: 6
A39: 45964 | B39: TU Chunks cells-02 | C39: 1 | D39: 0 | E39: No.29_Clone8-TU cell-02 | F39: Alive | H39: Alive normal | I39: Day 8 | J39: 6
A40: 45968 | B40: AB Chunks cells-04 | C40: 1 | D40: 0 | E40: No.30_Clone2-AB cell-04 | F40: Alive | H40: Alive normal | I40: Day 4 | J40: 7
A41: 45968 | B41: AB Chunks cells-04 | C41: 1 | D41: 0 | E41: No.31_Clone5-AB cell-04 | F41: Alive | H41: Alive normal | I41: Day 4 | J41: 7

Sheet % of development
A1: No. | B1: Name of cell | C1: Total Egg | D1: Activated | E1: 2-cell | F1: 4-cell | G1: 8-cell | H1: 16-cell | I1: 32-cell | J1: 64-cell | K1: 128-cell | L1: 256-cell | M1: 512-cell | N1: 1k-cell | O1: High | P1: Oblong | Q1: Sphere | R1: Dome | S1: 30%epi | T1: 50%epi | U1: Germ ring | V1: Shield | W1: 75%epi | X1: 90%epi | Y1: Day1 | Z1: Day2 | AA1: Day3 | AB1: Day4-5
A3: 1 | B3: AB | C3: ='raw data'!AZ3 -> 482 | D3: ='raw data'!AZ4 -> 482 | E3: ='raw data'!AZ5 -> 230 | F3: ='raw data'!AZ6 -> 213 | G3: ='raw data'!AZ7 -> 199 | H3: ='raw data'!AZ8 -> 179 | I3: ='raw data'!AZ9 -> 174 | J3: ='raw data'!AZ10 -> 173 | K3: ='raw data'!AZ11 -> 169 | L3: ='raw data'!AZ12 -> 169 | M3: ='raw data'!AZ13 -> 164 | N3: ='raw data'!AZ14 -> 157 | O3: ='raw data'!AZ15 -> 147 | P3: ='raw data'!AZ16 -> 131 | Q3: ='raw data'!AZ17 -> 114 | R3: ='raw data'!AZ18 -> 79 | S3: ='raw data'!AZ19 -> 54 | T3: ='raw data'!AZ20 -> 38 | U3: ='raw data'!AZ21 -> 36 | V3: ='raw data'!AZ22 -> 29 | W3: ='raw data'!AZ23 -> 19 | X3: ='raw data'!AZ24 -> 14 | Y3: ='raw data'!AZ25 -> 11 | Z3: ='raw data'!AZ26 -> 11
D4: % | E4: % | F4: % | G4: % | H4: % | I4: % | J4: % | K4: % | L4: % | M4: % | N4: % | O4: % | P4: % | Q4: % | R4: % | S4: % | T4: % | U4: % | V4: % | W4: % | X4: % | Y4: % | Z4: %
D5: ='raw data'!BA4 -> 100 | E5: ='raw data'!BA5 -> 47.717842 | F5: ='raw data'!BA6 -> 44.190871 | G5: ='raw data'!BA7 -> 41.286307 | H5: ='raw data'!BA8 -> 37.136929 | I5: ='raw data'!BA9 -> 36.099585 | J5: ='raw data'!BA10 -> 35.892116 | K5: ='raw data'!BA11 -> 35.062241 | L5: ='raw data'!BA12 -> 35.062241 | M5: ='raw data'!BA13 -> 34.024896 | N5: ='raw data'!BA14 -> 32.572614 | O5: ='raw data'!BA15 -> 30.497925 | P5: ='raw data'!BA16 -> 27.178423 | Q5: ='raw data'!BA17 -> 23.651452 | R5: ='raw data'!BA18 -> 16.390041 | S5: ='raw data'!BA19 -> 11.20332 | T5: ='raw data'!BA20 -> 7.8838174 | U5: ='raw data'!BA21 -> 7.4688797 | V5: ='raw data'!BA22 -> 6.0165975 | W5: ='raw data'!BA23 -> 3.9419087 | X5: ='raw data'!BA24 -> 2.9045643 | Y5: ='raw data'!BA25 -> 2.2821577 | Z5: ='raw data'!BA26 -> 2.2821577
A6: 2 | B6: TU | C6: ='raw data'!AV3 -> 450 | D6: ='raw data'!AV4 -> 450 | E6: ='raw data'!AV5 -> 203 | F6: ='raw data'!AV6 -> 185 | G6: ='raw data'!AV7 -> 169 | H6: ='raw data'!AV8 -> 156 | I6: ='raw data'!AV9 -> 145 | J6: ='raw data'!AV10 -> 144 | K6: ='raw data'!AV11 -> 143 | L6: ='raw data'!AV12 -> 140 | M6: ='raw data'!AV13 -> 135 | N6: ='raw data'!AV14 -> 134 | O6: ='raw data'!AV15 -> 120 | P6: ='raw data'!AV16 -> 110 | Q6: ='raw data'!AV17 -> 102 | R6: ='raw data'!AV18 -> 64 | S6: ='raw data'!AV19 -> 39 | T6: ='raw data'!AV20 -> 24 | U6: ='raw data'!AV21 -> 22 | V6: ='raw data'!AV22 -> 20 | W6: ='raw data'!AV23 -> 11 | X6: ='raw data'!AV24 -> 8 | Y6: ='raw data'!AV25 -> 8 | Z6: ='raw data'!AV26 -> 8
D7: % | E7: % | F7: % | G7: % | H7: % | I7: % | J7: % | K7: % | L7: % | M7: % | N7: % | O7: % | P7: % | Q7: % | R7: % | S7: % | T7: % | U7: % | V7: % | W7: % | X7: % | Y7: % | Z7: %
D8: ='raw data'!AW4 -> 100 | E8: ='raw data'!AW5 -> 45.111111 | F8: ='raw data'!AW6 -> 41.111111 | G8: ='raw data'!AW7 -> 37.555556 | H8: ='raw data'!AW8 -> 34.666667 | I8: ='raw data'!AW9 -> 32.222222 | J8: ='raw data'!AW10 -> 32 | K8: ='raw data'!AW11 -> 31.777778 | L8: ='raw data'!AW12 -> 31.111111 | M8: ='raw data'!AW13 -> 30 | N8: ='raw data'!AW14 -> 29.777778 | O8: ='raw data'!AW15 -> 26.666667 | P8: ='raw data'!AW16 -> 24.444444 | Q8: ='raw data'!AW17 -> 22.666667 | R8: ='raw data'!AW18 -> 14.222222 | S8: ='raw data'!AW19 -> 8.6666667 | T8: ='raw data'!AW20 -> 5.3333333 | U8: ='raw data'!AW21 -> 4.8888889 | V8: ='raw data'!AW22 -> 4.4444444 | W8: ='raw data'!AW23 -> 2.4444444 | X8: ='raw data'!AW24 -> 1.7777778 | Y8: ='raw data'!AW25 -> 1.7777778 | Z8: ='raw data'!AW26 -> 1.7777778
A9: 3 | B9: NHGRI | C9: ='raw data'!AX3 -> 484 | D9: ='raw data'!AX4 -> 484 | E9: ='raw data'!AX5 -> 234 | F9: ='raw data'!AX6 -> 220 | G9: ='raw data'!AX7 -> 210 | H9: ='raw data'!AX8 -> 201 | I9: ='raw data'!AX9 -> 193 | J9: ='raw data'!AX10 -> 190 | K9: ='raw data'!AX11 -> 180 | L9: ='raw data'!AX12 -> 178 | M9: ='raw data'!AX13 -> 172 | N9: ='raw data'!AX14 -> 168 | O9: ='raw data'!AX15 -> 162 | P9: ='raw data'!AX16 -> 146 | Q9: ='raw data'!AX17 -> 127 | R9: ='raw data'!AX18 -> 93 | S9: ='raw data'!AX19 -> 79 | T9: ='raw data'!AX20 -> 68 | U9: ='raw data'!AX21 -> 68 | V9: ='raw data'!AX22 -> 56 | W9: ='raw data'!AX23 -> 51 | X9: ='raw data'!AX24 -> 34 | Y9: ='raw data'!AX25 -> 27 | Z9: ='raw data'!AX26 -> 27
D10: % | E10: % | F10: % | G10: % | H10: % | I10: % | J10: % | K10: % | L10: % | M10: % | N10: % | O10: % | P10: % | Q10: % | R10: % | S10: % | T10: % | U10: % | V10: % | W10: % | X10: % | Y10: % | Z10: %
D11: ='raw data'!AY4 -> 100 | E11: ='raw data'!AY5 -> 48.347107 | F11: ='raw data'!AY6 -> 45.454545 | G11: ='raw data'!AY7 -> 43.38843 | H11: ='raw data'!AY8 -> 41.528926 | I11: ='raw data'!AY9 -> 39.876033 | J11: ='raw data'!AY10 -> 39.256198 | K11: ='raw data'!AY11 -> 37.190083 | L11: ='raw data'!AY12 -> 36.77686 | M11: ='raw data'!AY13 -> 35.53719 | N11: ='raw data'!AY14 -> 34.710744 | O11: ='raw data'!AY15 -> 33.471074 | P11: ='raw data'!AY16 -> 30.165289 | Q11: ='raw data'!AY17 -> 26.239669 | R11: ='raw data'!AY18 -> 19.214876 | S11: ='raw data'!AY19 -> 16.322314 | T11: ='raw data'!AY20 -> 14.049587 | U11: ='raw data'!AY21 -> 14.049587 | V11: ='raw data'!AY22 -> 11.570248 | W11: ='raw data'!AY23 -> 10.53719 | X11: ='raw data'!AY24 -> 7.0247934 | Y11: ='raw data'!AY25 -> 5.5785124 | Z11: ='raw data'!AY26 -> 5.5785124

Sheet NBD

Sheet Cloned fish status
A1: DOB | B1: Lot.CSOF | C1: Name of cell | E1: Code | F1: STATUS | G1: Normal | H1: Abnormal | I1: SEX | J1: cut tail | K1: AGE of clone | L1: d1 | M1: d2 | N1: d3 | O1: d4 | P1: d5 | Q1: d6 | R1: d7 | S1: d8 | T1: d9 | U1: d10 | V1: d11 | W1: d12 | X1: d13 | Y1: d14 | Z1: d15 | AA1: d16 | AB1: d17 | AC1: d18 | AD1: d19 | AE1: d20 | AF1: d21 | AG1: d22 | AH1: d23 | AI1: d24 | AJ1: d25 | AK1: d26 | AL1: d27 | AM1: d28 | AN1: d29 | AO1: d30 | AP1: d31 | AQ1: d32 | AR1: d33 | AS1: d34 | AT1: d35 | AU1: d36 | AV1: d37 | AW1: d38 | AX1: d39 | AY1: d40 | AZ1: d41 | BA1: d42 | BB1: d43 | BC1: d44 | BD1: d45 | BE1: d46 | BF1: d47 | BG1: d48 | BH1: d49 | BI1: d50 | BJ1: d51 | BK1: d52 | BL1: d53 | BM1: d54 | BN1: d55 | BO1: d56 | BP1: d57 | BQ1: d58 | BR1: d59 | BS1: d60 | BT1: d61 | BU1: d62 | BV1: d63 | BW1: d64 | BX1: d65 | BY1: d66 | BZ1: d67 | CA1: d68 | CB1: d69 | CC1: d70 | CD1: d71 | CE1: d72 | CF1: d73 | CG1: d74 | CH1: d75 | CI1: d76 | CJ1: d77 | CK1: d78 | CL1: d79 | CM1: d80 | CN1: d81 | CO1: d82 | CP1: d83 | CQ1: d84 | CR1: d85 | CS1: d86 | CT1: d87 | CU1: d88 | CV1: d89 | CW1: d90 | CX1: d91 | CY1: d92 | CZ1: d93 | DA1: d94 | DB1: d95 | DC1: d96 | DD1: d97 | DE1: d98 | DF1: d99 | DG1: d100 | DH1: d101 | DI1: d102 | DJ1: d103 | DK1: d104 | DL1: d105 | DM1: d106 | DN1: d107 | DO1: d108 | DP1: d109 | DQ1: d110 | DR1: d111 | DS1: d112 | DT1: d113 | DU1: d114 | DV1: d115 | DW1: d116 | DX1: d117 | DY1: d118 | DZ1: d119 | EA1: d120 | EB1: d121 | EC1: d122 | ED1: d123 | EE1: d124 | EF1: d125 | EG1: d126 | EH1: d127 | EI1: d128 | EJ1: d129 | EK1: d130 | EL1: d131 | EM1: d132 | EN1: d133 | EO1: d134 | EP1: d135 | EQ1: d136 | ER1: d137 | ES1: d138 | ET1: d139 | EU1: d140 | EV1: d141 | EW1: d142 | EX1: d143 | EY1: d144 | EZ1: d145 | FA1: d146 | FB1: d147 | FC1: d148 | FD1: d149 | FE1: d150 | FF1: d151 | FG1: d152 | FH1: d153 | FI1: d154 | FJ1: d155 | FK1: d156 | FL1: d157 | FM1: d158 | FN1: d159 | FO1: d160 | FP1: d161 | FQ1: d162 | FR1: d163 | FS1: d164 | FT1: d165 | FU1: d166 | FV1: d167 | FW1: d168 | FX1: d169 | FY1: d170 | FZ1: d171 | GA1: d172 | GB1: d173 | GC1: d174 | GD1: d175 | GE1: d176 | GF1: d177 | GG1: d178 | GH1: d179 | GI1: d180 | GJ1: d181 | GK1: d182 | GL1: d183 | GM1: d184 | GN1: d185 | GO1: d186 | GP1: d187 | GQ1: d188 | GR1: d189 | GS1: d190 | GT1: d191 | GU1: d192 | GV1: d193 | GW1: d194 | GX1: d195 | GY1: d196 | GZ1: d197 | HA1: d198 | HB1: d199 | HC1: d200 | HD1: d201 | HE1: d202 | HF1: d203 | HG1: d204 | HH1: d205 | HI1: d206 | HJ1: d207 | HK1: d208 | HL1: d209 | HM1: d210 | HN1: d211 | HO1: d212 | HP1: d213 | HQ1: d214 | HR1: d215 | HS1: d216 | HT1: d217 | HU1: d218 | HV1: d219 | HW1: d220 | HY1: Date of Freeze -20 | HZ1: Remarks | IA1: Status (@2025-11-11) | IB1: Zebrafish box | IC1: Remarks
A2: 45916 | B2: CSOF 2024-19 | C2: NHGRI dissociated cells-11 | D2: NHGRI | E2: No.1_Clone3-NHGRI cell-11 | F2: Frozen | G2: 0 | H2: 1 | K2: =SUM(L2:BW2) -> 6 | L2: 1 | M2: 1 | N2: 1 | O2: 1 | P2: 1 | Q2: 1 | HX2: 45922 | HY2: alive/abnormal freeze at Day 6 | HZ2: Freeze | IA2: -
A3: 45918 | B3: CSOF 2024-19 | C3: TU dissociated cells-12 | D3: TU | E3: No.2_Clone6-TU cell-12 | F3: Frozen | G3: 1 | H3: 0 | K3: =SUM(L3:BW3) -> 7 | L3: 1 | M3: 1 | N3: 1 | O3: 1 | P3: 1 | Q3: 1 | R3: 1 | S3: 0 | HX3: 45926 | HY3: death at day 8 | HZ3: Freeze | IA3: -
A4: 45923 | B4: CSOF 2024-27 | C4: NHGRI dissociated cells-12 | D4: NHGRI | E4: No.3_Clone2-NHGRI cell-12 | F4: Frozen | G4: 0 | H4: 1 | K4: =SUM(L4:BW4) -> 7 | L4: 1 | M4: 1 | N4: 1 | O4: 1 | P4: 1 | Q4: 1 | R4: 1 | HX4: 45930 | HY4: alive/abnormal freeze at Day 7 | HZ4: Freeze | IA4: -
A5: 45923 | B5: CSOF 2024-27 | C5: NHGRI dissociated cells-12 | D5: NHGRI | E5: No.4_Clone3-NHGRI cell-12 | F5: Frozen | G5: 0 | H5: 1 | K5: =SUM(L5:BW5) -> 7 | L5: 1 | M5: 1 | N5: 1 | O5: 1 | P5: 1 | Q5: 1 | R5: 1 | HX5: 45930 | HY5: alive/abnormal freeze at Day 7 | HZ5: Freeze | IA5: -
A6: 45926 | B6: CSOF 2024-27 | C6: AB dissociated cells-16 | D6: AB | E6: No.5_Clone1-AB cell-16 | F6: Frozen | G6: 0 | H6: 1 | K6: =SUM(L6:BW6) -> 7 | L6: 1 | M6: 1 | N6: 1 | O6: 1 | P6: 1 | Q6: 1 | R6: 1 | HX6: 45930 | HY6: alive/abnormal freeze at Day 7 | HZ6: Freeze | IA6: -
A7: 45926 | B7: CSOF 2024-27 | C7: AB dissociated cells-16 | D7: AB | E7: No.6_Clone3-AB cell-16 | F7: Alive | G7: 1 | H7: 0 | I7: M | J7: FALSE | K7: =SUM(L7:HE7) -> 201 | L7: 1 | M7: 1 | N7: 1 | O7: 1 | P7: 1 | Q7: 1 | R7: 1 | S7: 1 | T7: 1 | U7: 1 | V7: 1 | W7: 1 | X7: 1 | Y7: 1 | Z7: 1 | AA7: 1 | AB7: 1 | AC7: 1 | AD7: 1 | AE7: 1 | AF7: 1 | AG7: 1 | AH7: 1 | AI7: 1 | AJ7: 1 | AK7: 1 | AL7: 1 | AM7: 1 | AN7: 1 | AO7: 1 | AP7: 1 | AQ7: 1 | AR7: 1 | AS7: 1 | AT7: 1 | AU7: 1 | AV7: 1 | AW7: 1 | AX7: 1 | AY7: 1 | AZ7: 1 | BA7: 1 | BB7: 1 | BC7: 1 | BD7: 1 | BE7: 1 | BF7: 1 | BG7: 1 | BH7: 1 | BI7: 1 | BJ7: 1 | BK7: 1 | BL7: 1 | BM7: 1 | BN7: 1 | BO7: 1 | BP7: 1 | BQ7: 1 | BR7: 1 | BS7: 1 | BT7: 1 | BU7: 1 | BV7: 1 | BW7: 1 | BX7: 1 | BY7: 1 | BZ7: 1 | CA7: 1 | CB7: 1 | CC7: 1 | CD7: 1 | CE7: 1 | CF7: 1 | CG7: 1 | CH7: 1 | CI7: 1 | CJ7: 1 | CK7: 1 | CL7: 1 | CM7: 1 | CN7: 1 | CO7: 1 | CP7: 1 | CQ7: 1 | CR7: 1 | CS7: 1 | CT7: 1 | CU7: 1 | CV7: 1 | CW7: 1 | CX7: 1 | CY7: 1 | CZ7: 1 | DA7: 1 | DB7: 1 | DC7: 1 | DD7: 1 | DE7: 1 | DF7: 1 | DG7: 1 | DH7: 1 | DI7: 1 | DJ7: 1 | DK7: 1 | DL7: 1 | DM7: 1 | DN7: 1 | DO7: 1 | DP7: 1 | DQ7: 1 | DR7: 1 | DS7: 1 | DT7: 1 | DU7: 1 | DV7: 1 | DW7: 1 | DX7: 1 | DY7: 1 | DZ7: 1 | EA7: 1 | EB7: 1 | EC7: 1 | ED7: 1 | EE7: 1 | EF7: 1 | EG7: 1 | EH7: 1 | EI7: 1 | EJ7: 1 | EK7: 1 | EL7: 1 | EM7: 1 | EN7: 1 | EO7: 1 | EP7: 1 | EQ7: 1 | ER7: 1 | ES7: 1 | ET7: 1 | EU7: 1 | EV7: 1 | EW7: 1 | EX7: 1 | EY7: 1 | EZ7: 1 | FA7: 1 | FB7: 1 | FC7: 1 | FD7: 1 | FE7: 1 | FF7: 1 | FG7: 1 | FH7: 1 | FI7: 1 | FJ7: 1 | FK7: 1 | FL7: 1 | FM7: 1 | FN7: 1 | FO7: 1 | FP7: 1 | FQ7: 1 | FR7: 1 | FS7: 1 | FT7: 1 | FU7: 1 | FV7: 1 | FW7: 1 | FX7: 1 | FY7: 1 | FZ7: 1 | GA7: 1 | GB7: 1 | GC7: 1 | GD7: 1 | GE7: 1 | GF7: 1 | GG7: 1 | GH7: 1 | GI7: 1 | GJ7: 1 | GK7: 1 | GL7: 1 | GM7: 1 | GN7: 1 | GO7: 1 | GP7: 1 | GQ7: 1 | GR7: 1 | GS7: 1 | GT7: 1 | GU7: 1 | GV7: 1 | GW7: 1 | GX7: 1 | GY7: 1 | GZ7: 1 | HA7: 1 | HB7: 1 | HC7: 1 | HD7: 1 | HX7: Alive | HY7: Normal alive at fish room 2025-09-29 | HZ7: Day 46 | IA7: 1
A8: 45926 | B8: CSOF 2024-27 | C8: AB dissociated cells-16 | D8: AB | E8: No.7_Clone5-AB cell-16 | F8: Frozen | G8: 0 | H8: 1 | K8: =SUM(L8:BW8) -> 4 | L8: 1 | M8: 1 | N8: 1 | O8: 1 | HX8: 45930 | HY8: alive/abnormal freeze at Day 4 | HZ8: Freeze | IA8: -
A9: 45932 | B9: CSOF 2024-27 | C9: NHGRI dissociated cells-13 | D9: NHGRI | E9: No.8_Clone5-NHGRI cell-13 | F9: Frozen | G9: 0 | H9: 1 | K9: =SUM(L9:BW9) -> 4 | L9: 1 | M9: 1 | N9: 1 | O9: 1 | HX9: 45932 | HY9: alive/abnormal freeze at Day 4 | HZ9: Freeze | IA9: -
A10: 45933 | B10: CSOF 2024-27 | C10: AB dissociated cells-17 | D10: AB | E10: No.9_Clone4-AB cell-17 | F10: Discarded | G10: 0 | H10: 1 | J10: FALSE | K10: =SUM(L10:BW10) -> 5 | L10: 1 | M10: 1 | N10: 1 | O10: 1 | P10: 1 | HX10: - | HY10: Alive abnormal/degenerate | HZ10: Disscard | IA10: -
A11: 45933 | B11: CSOF 2024-27 | C11: AB dissociated cells-17 | D11: AB | E11: No.10_Clone4-AB cell-17 | F11: Frozen | G11: 0 | H11: 1 | K11: =SUM(L11:BW11) -> 10 | L11: 1 | M11: 1 | N11: 1 | O11: 1 | P11: 1 | Q11: 1 | R11: 1 | S11: 1 | T11: 1 | U11: 1 | HX11: 45940 | HY11: alive/abnormal freeze at Day 7 | HZ11: Freeze | IA11: -
